{
  "version": 8,
  "blockIdVersion": 11,
  "anchorX": 0,
  "anchorY": 0,
  "anchorZ": 0,
  "blocks": [
    {
      "x": -26,
      "y": 0,
      "z": -26,
      "name": "Soil_Dirt"
    },
    {
      "x": -26,
      "y": 0,
      "z": -25,
      "name": "Soil_Dirt"
    },
    {
      "x": -26,
      "y": 0,
      "z": -24,
      "name": "Soil_Dirt"
    },
    {
      "x": -26,
      "y": 0,
      "z": -23,
      "name": "Soil_Dirt"
    },
    {
      "x": -26,
      "y": 0,
      "z": -22,
      "name": "Soil_Dirt"
    },
    {
      "x": -26,
      "y": 0,
      "z": -21,
      "name": "Soil_Dirt"
    },
    {
      "x": -26,
      "y": 0,
      "z": -20,
      "name": "Soil_Dirt"
    },
    {
      "x": -26,
      "y": 0,
      "z": -19,
      "name": "Soil_Dirt"
    },
    {
      "x": -26,
      "y": 0,
      "z": -18,
      "name": "Soil_Dirt"
    },
    {
      "x": -26,
      "y": 0,
      "z": -17,
      "name": "Soil_Dirt"
    },
    {
      "x": -26,
      "y": 0,
      "z": -16,
      "name": "Soil_Dirt"
    },
    {
      "x": -26,
      "y": 0,
      "z": -15,
      "name": "Soil_Dirt"
    },
    {
      "x": -26,
      "y": 0,
      "z": -14,
      "name": "Soil_Dirt"
    },
    {
      "x": -26,
      "y": 0,
      "z": -13,
      "name": "Soil_Dirt"
    },
    {
      "x": -26,
      "y": 0,
      "z": -12,
      "name": "Soil_Dirt"
    },
    {
      "x": -26,
      "y": 0,
      "z": -11,
      "name": "Soil_Dirt"
    },
    {
      "x": -26,
      "y": 0,
      "z": -10,
      "name": "Soil_Dirt"
    },
    {
      "x": -26,
      "y": 0,
      "z": -9,
      "name": "Soil_Dirt"
    },
    {
      "x": -26,
      "y": 0,
      "z": -8,
      "name": "Soil_Dirt"
    },
    {
      "x": -26,
      "y": 0,
      "z": -7,
      "name": "Soil_Dirt"
    },
    {
      "x": -26,
      "y": 0,
      "z": -6,
      "name": "Soil_Dirt"
    },
    {
      "x": -26,
      "y": 0,
      "z": -5,
      "name": "Soil_Dirt"
    },
    {
      "x": -26,
      "y": 0,
      "z": -4,
      "name": "Soil_Dirt"
    },
    {
      "x": -26,
      "y": 0,
      "z": -3,
      "name": "Soil_Dirt"
    },
    {
      "x": -26,
      "y": 0,
      "z": -2,
      "name": "Soil_Dirt"
    },
    {
      "x": -26,
      "y": 0,
      "z": -1,
      "name": "Soil_Dirt"
    },
    {
      "x": -26,
      "y": 0,
      "z": 0,
      "name": "Soil_Dirt"
    },
    {
      "x": -26,
      "y": 0,
      "z": 1,
      "name": "Soil_Dirt"
    },
    {
      "x": -26,
      "y": 0,
      "z": 2,
      "name": "Soil_Dirt"
    },
    {
      "x": -26,
      "y": 0,
      "z": 3,
      "name": "Soil_Dirt"
    },
    {
      "x": -26,
      "y": 0,
      "z": 4,
      "name": "Soil_Dirt"
    },
    {
      "x": -26,
      "y": 0,
      "z": 5,
      "name": "Soil_Dirt"
    },
    {
      "x": -26,
      "y": 0,
      "z": 6,
      "name": "Soil_Dirt"
    },
    {
      "x": -26,
      "y": 0,
      "z": 7,
      "name": "Soil_Dirt"
    },
    {
      "x": -26,
      "y": 0,
      "z": 8,
      "name": "Soil_Dirt"
    },
    {
      "x": -26,
      "y": 0,
      "z": 9,
      "name": "Soil_Dirt"
    },
    {
      "x": -26,
      "y": 0,
      "z": 10,
      "name": "Soil_Dirt"
    },
    {
      "x": -26,
      "y": 0,
      "z": 11,
      "name": "Soil_Dirt"
    },
    {
      "x": -25,
      "y": 0,
      "z": -26,
      "name": "Soil_Dirt"
    },
    {
      "x": -25,
      "y": 0,
      "z": -25,
      "name": "Soil_Dirt"
    },
    {
      "x": -25,
      "y": 1,
      "z": -25,
      "name": "Soil_Clay_Smooth_Black"
    },
    {
      "x": -25,
      "y": 2,
      "z": -25,
      "name": "Rock_Volcanic_Brick_Smooth"
    },
    {
      "x": -25,
      "y": 3,
      "z": -25,
      "name": "Rock_Volcanic_Brick_Smooth"
    },
    {
      "x": -25,
      "y": 4,
      "z": -25,
      "name": "Rock_Volcanic_Brick"
    },
    {
      "x": -25,
      "y": 5,
      "z": -25,
      "name": "Rock_Volcanic_Brick_Ornate"
    },
    {
      "x": -25,
      "y": 6,
      "z": -25,
      "name": "Rock_Volcanic_Brick_Smooth"
    },
    {
      "x": -25,
      "y": 0,
      "z": -24,
      "name": "Soil_Dirt"
    },
    {
      "x": -25,
      "y": 1,
      "z": -24,
      "name": "Soil_Clay_Smooth_Black"
    },
    {
      "x": -25,
      "y": 2,
      "z": -24,
      "name": "Rock_Volcanic_Brick"
    },
    {
      "x": -25,
      "y": 3,
      "z": -24,
      "name": "Rock_Volcanic_Brick_Ornate"
    },
    {
      "x": -25,
      "y": 4,
      "z": -24,
      "name": "Rock_Volcanic_Brick_Ornate"
    },
    {
      "x": -25,
      "y": 5,
      "z": -24,
      "name": "Rock_Volcanic_Brick_Smooth"
    },
    {
      "x": -25,
      "y": 6,
      "z": -24,
      "name": "Rock_Volcanic_Brick"
    },
    {
      "x": -25,
      "y": 0,
      "z": -23,
      "name": "Soil_Dirt"
    },
    {
      "x": -25,
      "y": 1,
      "z": -23,
      "name": "Rock_Volcanic"
    },
    {
      "x": -25,
      "y": 2,
      "z": -23,
      "name": "Rock_Volcanic_Brick_Smooth"
    },
    {
      "x": -25,
      "y": 3,
      "z": -23,
      "name": "Rock_Volcanic_Brick_Smooth"
    },
    {
      "x": -25,
      "y": 4,
      "z": -23,
      "name": "Rock_Volcanic_Brick_Smooth"
    },
    {
      "x": -25,
      "y": 5,
      "z": -23,
      "name": "Rock_Volcanic_Brick_Smooth"
    },
    {
      "x": -25,
      "y": 6,
      "z": -23,
      "name": "Deco_Iron_Bars",
      "rotation": 1
    },
    {
      "x": -25,
      "y": 0,
      "z": -22,
      "name": "Soil_Dirt"
    },
    {
      "x": -25,
      "y": 1,
      "z": -22,
      "name": "Soil_Clay_Smooth_Black"
    },
    {
      "x": -25,
      "y": 2,
      "z": -22,
      "name": "Rock_Volcanic_Brick_Decorative"
    },
    {
      "x": -25,
      "y": 3,
      "z": -22,
      "name": "Rock_Volcanic_Brick_Smooth"
    },
    {
      "x": -25,
      "y": 4,
      "z": -22,
      "name": "Rock_Volcanic_Brick_Smooth"
    },
    {
      "x": -25,
      "y": 5,
      "z": -22,
      "name": "Deco_Iron_Bars",
      "rotation": 1
    },
    {
      "x": -25,
      "y": 0,
      "z": -21,
      "name": "Soil_Dirt"
    },
    {
      "x": -25,
      "y": 1,
      "z": -21,
      "name": "Rock_Volcanic_Half"
    },
    {
      "x": -25,
      "y": 2,
      "z": -21,
      "name": "Rock_Volcanic_Brick_Ornate"
    },
    {
      "x": -25,
      "y": 3,
      "z": -21,
      "name": "Rock_Volcanic_Brick_Smooth"
    },
    {
      "x": -25,
      "y": 4,
      "z": -21,
      "name": "Rock_Volcanic_Brick"
    },
    {
      "x": -25,
      "y": 5,
      "z": -21,
      "name": "Rock_Volcanic_Brick"
    },
    {
      "x": -25,
      "y": 6,
      "z": -21,
      "name": "Deco_Iron_Bars",
      "rotation": 1
    },
    {
      "x": -25,
      "y": 0,
      "z": -20,
      "name": "Soil_Dirt"
    },
    {
      "x": -25,
      "y": 1,
      "z": -20,
      "name": "Soil_Clay_Smooth_Black"
    },
    {
      "x": -25,
      "y": 2,
      "z": -20,
      "name": "Rock_Volcanic_Brick_Smooth"
    },
    {
      "x": -25,
      "y": 3,
      "z": -20,
      "name": "Rock_Volcanic_Brick_Ornate"
    },
    {
      "x": -25,
      "y": 4,
      "z": -20,
      "name": "Rock_Volcanic_Brick_Decorative"
    },
    {
      "x": -25,
      "y": 0,
      "z": -19,
      "name": "Soil_Dirt"
    },
    {
      "x": -25,
      "y": 1,
      "z": -19,
      "name": "Soil_Clay_Smooth_Black"
    },
    {
      "x": -25,
      "y": 2,
      "z": -19,
      "name": "Rock_Volcanic_Brick_Decorative"
    },
    {
      "x": -25,
      "y": 3,
      "z": -19,
      "name": "Rock_Volcanic_Brick_Smooth"
    },
    {
      "x": -25,
      "y": 4,
      "z": -19,
      "name": "Rock_Volcanic_Brick_Decorative"
    },
    {
      "x": -25,
      "y": 5,
      "z": -19,
      "name": "Rock_Volcanic_Brick_Smooth"
    },
    {
      "x": -25,
      "y": 0,
      "z": -18,
      "name": "Soil_Dirt"
    },
    {
      "x": -25,
      "y": 1,
      "z": -18,
      "name": "Soil_Clay_Smooth_Black"
    },
    {
      "x": -25,
      "y": 2,
      "z": -18,
      "name": "Rock_Volcanic_Brick"
    },
    {
      "x": -25,
      "y": 3,
      "z": -18,
      "name": "Rock_Volcanic_Brick_Smooth"
    },
    {
      "x": -25,
      "y": 4,
      "z": -18,
      "name": "Rock_Volcanic_Brick_Decorative"
    },
    {
      "x": -25,
      "y": 5,
      "z": -18,
      "name": "Deco_Iron_Bars",
      "rotation": 1
    },
    {
      "x": -25,
      "y": 0,
      "z": -17,
      "name": "Soil_Dirt"
    },
    {
      "x": -25,
      "y": 1,
      "z": -17,
      "name": "Rock_Volcanic_Half"
    },
    {
      "x": -25,
      "y": 2,
      "z": -17,
      "name": "Rock_Volcanic_Brick_Ornate"
    },
    {
      "x": -25,
      "y": 3,
      "z": -17,
      "name": "Rock_Volcanic_Brick_Smooth"
    },
    {
      "x": -25,
      "y": 4,
      "z": -17,
      "name": "Rock_Volcanic_Brick_Smooth"
    },
    {
      "x": -25,
      "y": 5,
      "z": -17,
      "name": "Deco_Iron_Bars",
      "rotation": 1
    },
    {
      "x": -25,
      "y": 0,
      "z": -16,
      "name": "Soil_Dirt"
    },
    {
      "x": -25,
      "y": 1,
      "z": -16,
      "name": "Soil_Clay_Smooth_Black"
    },
    {
      "x": -25,
      "y": 2,
      "z": -16,
      "name": "Rock_Volcanic_Brick_Smooth"
    },
    {
      "x": -25,
      "y": 3,
      "z": -16,
      "name": "Rock_Volcanic_Brick_Ornate"
    },
    {
      "x": -25,
      "y": 0,
      "z": -15,
      "name": "Soil_Dirt"
    },
    {
      "x": -25,
      "y": 1,
      "z": -15,
      "name": "Soil_Clay_Smooth_Black"
    },
    {
      "x": -25,
      "y": 2,
      "z": -15,
      "name": "Rock_Volcanic_Brick_Decorative"
    },
    {
      "x": -25,
      "y": 3,
      "z": -15,
      "name": "Rock_Volcanic_Brick"
    },
    {
      "x": -25,
      "y": 0,
      "z": -14,
      "name": "Soil_Dirt"
    },
    {
      "x": -25,
      "y": 1,
      "z": -14,
      "name": "Rock_Volcanic_Half"
    },
    {
      "x": -25,
      "y": 2,
      "z": -14,
      "name": "Rock_Volcanic_Brick_Decorative"
    },
    {
      "x": -25,
      "y": 3,
      "z": -14,
      "name": "Rock_Volcanic_Brick_Smooth"
    },
    {
      "x": -25,
      "y": 4,
      "z": -14,
      "name": "Rock_Volcanic_Brick_Ornate"
    },
    {
      "x": -25,
      "y": 0,
      "z": -13,
      "name": "Soil_Dirt"
    },
    {
      "x": -25,
      "y": 1,
      "z": -13,
      "name": "Soil_Clay_Smooth_Black"
    },
    {
      "x": -25,
      "y": 2,
      "z": -13,
      "name": "Rock_Volcanic_Brick_Ornate"
    },
    {
      "x": -25,
      "y": 3,
      "z": -13,
      "name": "Rock_Volcanic_Brick_Smooth"
    },
    {
      "x": -25,
      "y": 4,
      "z": -13,
      "name": "Deco_Iron_Bars",
      "rotation": 1
    },
    {
      "x": -25,
      "y": 0,
      "z": -12,
      "name": "Soil_Dirt"
    },
    {
      "x": -25,
      "y": 1,
      "z": -12,
      "name": "Soil_Clay_Smooth_Black"
    },
    {
      "x": -25,
      "y": 2,
      "z": -12,
      "name": "Rock_Volcanic_Brick_Smooth"
    },
    {
      "x": -25,
      "y": 3,
      "z": -12,
      "name": "Rock_Volcanic_Brick_Smooth"
    },
    {
      "x": -25,
      "y": 4,
      "z": -12,
      "name": "Rock_Volcanic_Brick_Smooth"
    },
    {
      "x": -25,
      "y": 0,
      "z": -11,
      "name": "Soil_Dirt"
    },
    {
      "x": -25,
      "y": 1,
      "z": -11,
      "name": "Rock_Volcanic"
    },
    {
      "x": -25,
      "y": 2,
      "z": -11,
      "name": "Rock_Volcanic_Brick"
    },
    {
      "x": -25,
      "y": 3,
      "z": -11,
      "name": "Rock_Volcanic_Brick_Smooth"
    },
    {
      "x": -25,
      "y": 4,
      "z": -11,
      "name": "Rock_Volcanic_Brick_Smooth"
    },
    {
      "x": -25,
      "y": 5,
      "z": -11,
      "name": "Rock_Volcanic_Brick_Ornate"
    },
    {
      "x": -25,
      "y": 6,
      "z": -11,
      "name": "Deco_Iron_Bars",
      "rotation": 1
    },
    {
      "x": -25,
      "y": 0,
      "z": -10,
      "name": "Soil_Dirt"
    },
    {
      "x": -25,
      "y": 1,
      "z": -10,
      "name": "Soil_Clay_Smooth_Black"
    },
    {
      "x": -25,
      "y": 2,
      "z": -10,
      "name": "Rock_Volcanic_Brick_Smooth"
    },
    {
      "x": -25,
      "y": 5,
      "z": -10,
      "name": "Deco_Iron_Bars",
      "rotation": 1
    },
    {
      "x": -25,
      "y": 0,
      "z": -9,
      "name": "Soil_Dirt"
    },
    {
      "x": -25,
      "y": 1,
      "z": -9,
      "name": "Soil_Clay_Smooth_Black"
    },
    {
      "x": -25,
      "y": 2,
      "z": -9,
      "name": "Rock_Volcanic_Brick_Smooth"
    },
    {
      "x": -25,
      "y": 3,
      "z": -9,
      "name": "Rock_Volcanic_Brick"
    },
    {
      "x": -25,
      "y": 4,
      "z": -9,
      "name": "Deco_Iron_Bars",
      "rotation": 1
    },
    {
      "x": -25,
      "y": 0,
      "z": -8,
      "name": "Soil_Dirt"
    },
    {
      "x": -25,
      "y": 1,
      "z": -8,
      "name": "Rock_Volcanic_Half"
    },
    {
      "x": -25,
      "y": 2,
      "z": -8,
      "name": "Rock_Volcanic_Brick_Smooth"
    },
    {
      "x": -25,
      "y": 3,
      "z": -8,
      "name": "Rock_Volcanic_Brick_Smooth"
    },
    {
      "x": -25,
      "y": 4,
      "z": -8,
      "name": "Rock_Volcanic_Brick_Smooth"
    },
    {
      "x": -25,
      "y": 5,
      "z": -8,
      "name": "Rock_Volcanic_Brick_Smooth"
    },
    {
      "x": -25,
      "y": 6,
      "z": -8,
      "name": "Deco_Iron_Bars",
      "rotation": 1
    },
    {
      "x": -25,
      "y": 0,
      "z": -7,
      "name": "Soil_Dirt"
    },
    {
      "x": -25,
      "y": 1,
      "z": -7,
      "name": "Soil_Clay_Smooth_Black"
    },
    {
      "x": -25,
      "y": 2,
      "z": -7,
      "name": "Rock_Volcanic_Brick_Smooth"
    },
    {
      "x": -25,
      "y": 3,
      "z": -7,
      "name": "Rock_Volcanic_Brick_Smooth"
    },
    {
      "x": -25,
      "y": 4,
      "z": -7,
      "name": "Rock_Volcanic_Brick_Ornate"
    },
    {
      "x": -25,
      "y": 5,
      "z": -7,
      "name": "Deco_Iron_Bars",
      "rotation": 1
    },
    {
      "x": -25,
      "y": 0,
      "z": -6,
      "name": "Soil_Dirt"
    },
    {
      "x": -25,
      "y": 1,
      "z": -6,
      "name": "Rock_Volcanic_Half"
    },
    {
      "x": -25,
      "y": 2,
      "z": -6,
      "name": "Rock_Volcanic_Brick_Decorative"
    },
    {
      "x": -25,
      "y": 3,
      "z": -6,
      "name": "Rock_Volcanic_Brick_Smooth"
    },
    {
      "x": -25,
      "y": 4,
      "z": -6,
      "name": "Rock_Volcanic_Brick_Smooth"
    },
    {
      "x": -25,
      "y": 5,
      "z": -6,
      "name": "Rock_Volcanic_Brick_Ornate"
    },
    {
      "x": -25,
      "y": 0,
      "z": -5,
      "name": "Soil_Dirt"
    },
    {
      "x": -25,
      "y": 1,
      "z": -5,
      "name": "Soil_Clay_Smooth_Black"
    },
    {
      "x": -25,
      "y": 2,
      "z": -5,
      "name": "Rock_Volcanic_Brick_Smooth"
    },
    {
      "x": -25,
      "y": 3,
      "z": -5,
      "name": "Rock_Volcanic_Brick_Smooth"
    },
    {
      "x": -25,
      "y": 4,
      "z": -5,
      "name": "Deco_Iron_Bars",
      "rotation": 1
    },
    {
      "x": -25,
      "y": 0,
      "z": -4,
      "name": "Soil_Dirt"
    },
    {
      "x": -25,
      "y": 1,
      "z": -4,
      "name": "Soil_Clay_Smooth_Black"
    },
    {
      "x": -25,
      "y": 2,
      "z": -4,
      "name": "Rock_Volcanic_Brick_Decorative"
    },
    {
      "x": -25,
      "y": 3,
      "z": -4,
      "name": "Rock_Volcanic_Brick"
    },
    {
      "x": -25,
      "y": 0,
      "z": -3,
      "name": "Soil_Dirt"
    },
    {
      "x": -25,
      "y": 1,
      "z": -3,
      "name": "Soil_Clay_Smooth_Black"
    },
    {
      "x": -25,
      "y": 2,
      "z": -3,
      "name": "Rock_Volcanic_Brick_Smooth"
    },
    {
      "x": -25,
      "y": 3,
      "z": -3,
      "name": "Rock_Volcanic_Brick_Smooth"
    },
    {
      "x": -25,
      "y": 4,
      "z": -3,
      "name": "Rock_Volcanic_Brick"
    },
    {
      "x": -25,
      "y": 0,
      "z": -2,
      "name": "Soil_Dirt"
    },
    {
      "x": -25,
      "y": 1,
      "z": -2,
      "name": "Rock_Volcanic_Half"
    },
    {
      "x": -25,
      "y": 2,
      "z": -2,
      "name": "Rock_Volcanic_Brick_Smooth"
    },
    {
      "x": -25,
      "y": 4,
      "z": -2,
      "name": "Deco_Iron_Bars",
      "rotation": 1
    },
    {
      "x": -25,
      "y": 0,
      "z": -1,
      "name": "Soil_Dirt"
    },
    {
      "x": -25,
      "y": 1,
      "z": -1,
      "name": "Rock_Volcanic_Half"
    },
    {
      "x": -25,
      "y": 2,
      "z": -1,
      "name": "Rock_Volcanic_Brick_Ornate"
    },
    {
      "x": -25,
      "y": 3,
      "z": -1,
      "name": "Rock_Volcanic_Brick_Smooth"
    },
    {
      "x": -25,
      "y": 4,
      "z": -1,
      "name": "Deco_Iron_Bars",
      "rotation": 1
    },
    {
      "x": -25,
      "y": 5,
      "z": -1,
      "name": "Deco_Iron_Bars",
      "rotation": 1
    },
    {
      "x": -25,
      "y": 0,
      "z": 0,
      "name": "Soil_Dirt"
    },
    {
      "x": -25,
      "y": 1,
      "z": 0,
      "name": "Soil_Clay_Smooth_Black"
    },
    {
      "x": -25,
      "y": 2,
      "z": 0,
      "name": "Rock_Volcanic_Brick"
    },
    {
      "x": -25,
      "y": 3,
      "z": 0,
      "name": "Rock_Volcanic_Brick"
    },
    {
      "x": -25,
      "y": 4,
      "z": 0,
      "name": "Rock_Volcanic_Brick_Ornate"
    },
    {
      "x": -25,
      "y": 5,
      "z": 0,
      "name": "Rock_Volcanic_Brick"
    },
    {
      "x": -25,
      "y": 6,
      "z": 0,
      "name": "Rock_Volcanic_Brick"
    },
    {
      "x": -25,
      "y": 0,
      "z": 1,
      "name": "Soil_Dirt"
    },
    {
      "x": -25,
      "y": 1,
      "z": 1,
      "name": "Rock_Volcanic_Half"
    },
    {
      "x": -25,
      "y": 2,
      "z": 1,
      "name": "Rock_Volcanic_Brick_Smooth"
    },
    {
      "x": -25,
      "y": 3,
      "z": 1,
      "name": "Rock_Volcanic_Brick_Smooth"
    },
    {
      "x": -25,
      "y": 4,
      "z": 1,
      "name": "Rock_Volcanic_Brick_Smooth"
    },
    {
      "x": -25,
      "y": 5,
      "z": 1,
      "name": "Rock_Volcanic_Brick_Smooth"
    },
    {
      "x": -25,
      "y": 0,
      "z": 2,
      "name": "Soil_Dirt"
    },
    {
      "x": -25,
      "y": 1,
      "z": 2,
      "name": "Soil_Clay_Smooth_Black"
    },
    {
      "x": -25,
      "y": 2,
      "z": 2,
      "name": "Rock_Volcanic_Brick_Smooth"
    },
    {
      "x": -25,
      "y": 3,
      "z": 2,
      "name": "Rock_Volcanic_Brick"
    },
    {
      "x": -25,
      "y": 4,
      "z": 2,
      "name": "Rock_Volcanic_Brick_Smooth"
    },
    {
      "x": -25,
      "y": 5,
      "z": 2,
      "name": "Deco_Iron_Bars",
      "rotation": 1
    },
    {
      "x": -25,
      "y": 0,
      "z": 3,
      "name": "Soil_Dirt"
    },
    {
      "x": -25,
      "y": 1,
      "z": 3,
      "name": "Rock_Volcanic_Half"
    },
    {
      "x": -25,
      "y": 0,
      "z": 4,
      "name": "Soil_Dirt"
    },
    {
      "x": -25,
      "y": 1,
      "z": 4,
      "name": "Rock_Volcanic_Half"
    },
    {
      "x": -25,
      "y": 2,
      "z": 4,
      "name": "Rock_Volcanic_Brick_Decorative"
    },
    {
      "x": -25,
      "y": 3,
      "z": 4,
      "name": "Rock_Volcanic_Brick_Decorative"
    },
    {
      "x": -25,
      "y": 4,
      "z": 4,
      "name": "Deco_Iron_Bars",
      "rotation": 1
    },
    {
      "x": -25,
      "y": 0,
      "z": 5,
      "name": "Soil_Dirt"
    },
    {
      "x": -25,
      "y": 1,
      "z": 5,
      "name": "Soil_Clay_Smooth_Black"
    },
    {
      "x": -25,
      "y": 2,
      "z": 5,
      "name": "Rock_Volcanic_Brick"
    },
    {
      "x": -25,
      "y": 4,
      "z": 5,
      "name": "Deco_Iron_Bars",
      "rotation": 1
    },
    {
      "x": -25,
      "y": 0,
      "z": 6,
      "name": "Soil_Dirt"
    },
    {
      "x": -25,
      "y": 1,
      "z": 6,
      "name": "Soil_Clay_Smooth_Black"
    },
    {
      "x": -25,
      "y": 2,
      "z": 6,
      "name": "Rock_Volcanic_Brick"
    },
    {
      "x": -25,
      "y": 3,
      "z": 6,
      "name": "Rock_Volcanic_Brick_Ornate"
    },
    {
      "x": -25,
      "y": 4,
      "z": 6,
      "name": "Deco_Iron_Bars",
      "rotation": 1
    },
    {
      "x": -25,
      "y": 5,
      "z": 6,
      "name": "Deco_Iron_Bars",
      "rotation": 1
    },
    {
      "x": -25,
      "y": 0,
      "z": 7,
      "name": "Soil_Dirt"
    },
    {
      "x": -25,
      "y": 1,
      "z": 7,
      "name": "Soil_Clay_Smooth_Black"
    },
    {
      "x": -25,
      "y": 2,
      "z": 7,
      "name": "Rock_Volcanic_Brick"
    },
    {
      "x": -25,
      "y": 3,
      "z": 7,
      "name": "Rock_Volcanic_Brick_Smooth"
    },
    {
      "x": -25,
      "y": 4,
      "z": 7,
      "name": "Deco_Iron_Bars",
      "rotation": 1
    },
    {
      "x": -25,
      "y": 0,
      "z": 8,
      "name": "Soil_Dirt"
    },
    {
      "x": -25,
      "y": 1,
      "z": 8,
      "name": "Soil_Clay_Smooth_Black"
    },
    {
      "x": -25,
      "y": 2,
      "z": 8,
      "name": "Rock_Volcanic_Brick_Ornate"
    },
    {
      "x": -25,
      "y": 3,
      "z": 8,
      "name": "Rock_Volcanic_Brick_Smooth"
    },
    {
      "x": -25,
      "y": 4,
      "z": 8,
      "name": "Rock_Volcanic_Brick_Smooth"
    },
    {
      "x": -25,
      "y": 5,
      "z": 8,
      "name": "Rock_Volcanic_Brick"
    },
    {
      "x": -25,
      "y": 0,
      "z": 9,
      "name": "Soil_Dirt"
    },
    {
      "x": -25,
      "y": 0,
      "z": 10,
      "name": "Soil_Dirt"
    },
    {
      "x": -25,
      "y": 0,
      "z": 11,
      "name": "Soil_Dirt"
    },
    {
      "x": -25,
      "y": 0,
      "z": 12,
      "name": "Soil_Dirt"
    },
    {
      "x": -25,
      "y": 0,
      "z": 13,
      "name": "Soil_Dirt"
    },
    {
      "x": -25,
      "y": 0,
      "z": 14,
      "name": "Soil_Dirt"
    },
    {
      "x": -24,
      "y": 0,
      "z": -26,
      "name": "Soil_Dirt"
    },
    {
      "x": -24,
      "y": 0,
      "z": -25,
      "name": "Soil_Dirt"
    },
    {
      "x": -24,
      "y": 1,
      "z": -25,
      "name": "Soil_Clay_Smooth_Black"
    },
    {
      "x": -24,
      "y": 2,
      "z": -25,
      "name": "Deco_Iron_Bars"
    },
    {
      "x": -24,
      "y": 3,
      "z": -25,
      "name": "Deco_Iron_Bars"
    },
    {
      "x": -24,
      "y": 0,
      "z": -24,
      "name": "Soil_Dirt"
    },
    {
      "x": -24,
      "y": 1,
      "z": -24,
      "name": "Rock_Volcanic"
    },
    {
      "x": -24,
      "y": 0,
      "z": -23,
      "name": "Soil_Dirt"
    },
    {
      "x": -24,
      "y": 1,
      "z": -23,
      "name": "Soil_Clay_Smooth_Black"
    },
    {
      "x": -24,
      "y": 0,
      "z": -22,
      "name": "Soil_Dirt"
    },
    {
      "x": -24,
      "y": 1,
      "z": -22,
      "name": "Soil_Clay_Smooth_Black"
    },
    {
      "x": -24,
      "y": 0,
      "z": -21,
      "name": "Soil_Dirt"
    },
    {
      "x": -24,
      "y": 1,
      "z": -21,
      "name": "Rock_Volcanic"
    },
    {
      "x": -24,
      "y": 0,
      "z": -20,
      "name": "Soil_Dirt"
    },
    {
      "x": -24,
      "y": 1,
      "z": -20,
      "name": "Soil_Clay_Smooth_Black"
    },
    {
      "x": -24,
      "y": 0,
      "z": -19,
      "name": "Soil_Dirt"
    },
    {
      "x": -24,
      "y": 1,
      "z": -19,
      "name": "Soil_Clay_Smooth_Black"
    },
    {
      "x": -24,
      "y": 0,
      "z": -18,
      "name": "Soil_Dirt"
    },
    {
      "x": -24,
      "y": 1,
      "z": -18,
      "name": "Rock_Volcanic_Half"
    },
    {
      "x": -24,
      "y": 0,
      "z": -17,
      "name": "Soil_Dirt"
    },
    {
      "x": -24,
      "y": 1,
      "z": -17,
      "name": "Rock_Volcanic_Half"
    },
    {
      "x": -24,
      "y": 0,
      "z": -16,
      "name": "Soil_Dirt"
    },
    {
      "x": -24,
      "y": 1,
      "z": -16,
      "name": "Soil_Clay_Smooth_Black"
    },
    {
      "x": -24,
      "y": 0,
      "z": -15,
      "name": "Soil_Dirt"
    },
    {
      "x": -24,
      "y": 1,
      "z": -15,
      "name": "Rock_Volcanic_Half"
    },
    {
      "x": -24,
      "y": 0,
      "z": -14,
      "name": "Soil_Dirt"
    },
    {
      "x": -24,
      "y": 1,
      "z": -14,
      "name": "Soil_Clay_Smooth_Black"
    },
    {
      "x": -24,
      "y": 0,
      "z": -13,
      "name": "Soil_Dirt"
    },
    {
      "x": -24,
      "y": 1,
      "z": -13,
      "name": "Rock_Volcanic_Half"
    },
    {
      "x": -24,
      "y": 0,
      "z": -12,
      "name": "Soil_Dirt"
    },
    {
      "x": -24,
      "y": 1,
      "z": -12,
      "name": "Rock_Volcanic_Half"
    },
    {
      "x": -24,
      "y": 0,
      "z": -11,
      "name": "Soil_Dirt"
    },
    {
      "x": -24,
      "y": 1,
      "z": -11,
      "name": "Soil_Clay_Smooth_Black"
    },
    {
      "x": -24,
      "y": 0,
      "z": -10,
      "name": "Soil_Dirt"
    },
    {
      "x": -24,
      "y": 1,
      "z": -10,
      "name": "Soil_Clay_Smooth_Black"
    },
    {
      "x": -24,
      "y": 0,
      "z": -9,
      "name": "Soil_Dirt"
    },
    {
      "x": -24,
      "y": 1,
      "z": -9,
      "name": "Soil_Clay_Smooth_Black"
    },
    {
      "x": -24,
      "y": 0,
      "z": -8,
      "name": "Soil_Dirt"
    },
    {
      "x": -24,
      "y": 1,
      "z": -8,
      "name": "Rock_Volcanic"
    },
    {
      "x": -24,
      "y": 0,
      "z": -7,
      "name": "Soil_Dirt"
    },
    {
      "x": -24,
      "y": 1,
      "z": -7,
      "name": "Soil_Clay_Smooth_Black"
    },
    {
      "x": -24,
      "y": 0,
      "z": -6,
      "name": "Soil_Dirt"
    },
    {
      "x": -24,
      "y": 1,
      "z": -6,
      "name": "Soil_Clay_Smooth_Black"
    },
    {
      "x": -24,
      "y": 0,
      "z": -5,
      "name": "Soil_Dirt"
    },
    {
      "x": -24,
      "y": 1,
      "z": -5,
      "name": "Rock_Volcanic_Half"
    },
    {
      "x": -24,
      "y": 0,
      "z": -4,
      "name": "Soil_Dirt"
    },
    {
      "x": -24,
      "y": 1,
      "z": -4,
      "name": "Rock_Volcanic_Half"
    },
    {
      "x": -24,
      "y": 0,
      "z": -3,
      "name": "Soil_Dirt"
    },
    {
      "x": -24,
      "y": 1,
      "z": -3,
      "name": "Soil_Clay_Smooth_Black"
    },
    {
      "x": -24,
      "y": 0,
      "z": -2,
      "name": "Soil_Dirt"
    },
    {
      "x": -24,
      "y": 1,
      "z": -2,
      "name": "Soil_Clay_Smooth_Black"
    },
    {
      "x": -24,
      "y": 0,
      "z": -1,
      "name": "Soil_Dirt"
    },
    {
      "x": -24,
      "y": 1,
      "z": -1,
      "name": "Soil_Clay_Smooth_Black"
    },
    {
      "x": -24,
      "y": 0,
      "z": 0,
      "name": "Soil_Dirt"
    },
    {
      "x": -24,
      "y": 1,
      "z": 0,
      "name": "Soil_Clay_Smooth_Black"
    },
    {
      "x": -24,
      "y": 0,
      "z": 1,
      "name": "Soil_Dirt"
    },
    {
      "x": -24,
      "y": 1,
      "z": 1,
      "name": "Soil_Clay_Smooth_Black"
    },
    {
      "x": -24,
      "y": 0,
      "z": 2,
      "name": "Soil_Dirt"
    },
    {
      "x": -24,
      "y": 1,
      "z": 2,
      "name": "Soil_Clay_Smooth_Black"
    },
    {
      "x": -24,
      "y": 0,
      "z": 3,
      "name": "Soil_Dirt"
    },
    {
      "x": -24,
      "y": 1,
      "z": 3,
      "name": "Soil_Clay_Smooth_Black"
    },
    {
      "x": -24,
      "y": 0,
      "z": 4,
      "name": "Soil_Dirt"
    },
    {
      "x": -24,
      "y": 1,
      "z": 4,
      "name": "Soil_Clay_Smooth_Black"
    },
    {
      "x": -24,
      "y": 0,
      "z": 5,
      "name": "Soil_Dirt"
    },
    {
      "x": -24,
      "y": 1,
      "z": 5,
      "name": "Soil_Clay_Smooth_Black"
    },
    {
      "x": -24,
      "y": 0,
      "z": 6,
      "name": "Soil_Dirt"
    },
    {
      "x": -24,
      "y": 1,
      "z": 6,
      "name": "Soil_Clay_Smooth_Black"
    },
    {
      "x": -24,
      "y": 0,
      "z": 7,
      "name": "Soil_Dirt"
    },
    {
      "x": -24,
      "y": 1,
      "z": 7,
      "name": "Soil_Clay_Smooth_Black"
    },
    {
      "x": -24,
      "y": 0,
      "z": 8,
      "name": "Soil_Dirt"
    },
    {
      "x": -24,
      "y": 1,
      "z": 8,
      "name": "Soil_Clay_Smooth_Black"
    },
    {
      "x": -24,
      "y": 2,
      "z": 8,
      "name": "Rock_Volcanic_Brick_Decorative"
    },
    {
      "x": -24,
      "y": 3,
      "z": 8,
      "name": "Rock_Volcanic_Brick_Decorative"
    },
    {
      "x": -24,
      "y": 4,
      "z": 8,
      "name": "Rock_Volcanic_Brick_Smooth"
    },
    {
      "x": -24,
      "y": 5,
      "z": 8,
      "name": "Deco_Iron_Bars"
    },
    {
      "x": -24,
      "y": 0,
      "z": 9,
      "name": "Soil_Dirt"
    },
    {
      "x": -24,
      "y": 0,
      "z": 10,
      "name": "Soil_Dirt"
    },
    {
      "x": -24,
      "y": 0,
      "z": 11,
      "name": "Soil_Dirt"
    },
    {
      "x": -24,
      "y": 0,
      "z": 12,
      "name": "Soil_Dirt"
    },
    {
      "x": -24,
      "y": 0,
      "z": 13,
      "name": "Soil_Dirt"
    },
    {
      "x": -24,
      "y": 0,
      "z": 14,
      "name": "Soil_Dirt"
    },
    {
      "x": -24,
      "y": 0,
      "z": 15,
      "name": "Soil_Dirt"
    },
    {
      "x": -24,
      "y": 0,
      "z": 16,
      "name": "Soil_Dirt"
    },
    {
      "x": -24,
      "y": 0,
      "z": 17,
      "name": "Soil_Dirt"
    },
    {
      "x": -23,
      "y": 0,
      "z": -26,
      "name": "Soil_Dirt"
    },
    {
      "x": -23,
      "y": 0,
      "z": -25,
      "name": "Soil_Dirt"
    },
    {
      "x": -23,
      "y": 1,
      "z": -25,
      "name": "Soil_Clay_Smooth_Black"
    },
    {
      "x": -23,
      "y": 2,
      "z": -25,
      "name": "Rock_Volcanic_Brick_Smooth"
    },
    {
      "x": -23,
      "y": 3,
      "z": -25,
      "name": "Rock_Volcanic_Brick_Smooth"
    },
    {
      "x": -23,
      "y": 0,
      "z": -24,
      "name": "Soil_Dirt"
    },
    {
      "x": -23,
      "y": 1,
      "z": -24,
      "name": "Soil_Clay_Smooth_Black"
    },
    {
      "x": -23,
      "y": 0,
      "z": -23,
      "name": "Soil_Dirt"
    },
    {
      "x": -23,
      "y": 1,
      "z": -23,
      "name": "Soil_Clay_Smooth_Black"
    },
    {
      "x": -23,
      "y": 7,
      "z": -23,
      "name": "Factory_Roof_Steep",
      "rotation": 3
    },
    {
      "x": -23,
      "y": 8,
      "z": -23,
      "name": "Factory_Roof_Steep",
      "filler": 1024,
      "rotation": 3
    },
    {
      "x": -23,
      "y": 0,
      "z": -22,
      "name": "Soil_Dirt"
    },
    {
      "x": -23,
      "y": 1,
      "z": -22,
      "name": "Soil_Clay_Smooth_Black"
    },
    {
      "x": -23,
      "y": 2,
      "z": -22,
      "name": "Rock_Volcanic_Brick"
    },
    {
      "x": -23,
      "y": 7,
      "z": -22,
      "name": "Factory_Roof_Steep",
      "rotation": 3
    },
    {
      "x": -23,
      "y": 8,
      "z": -22,
      "name": "Factory_Roof_Steep",
      "filler": 1024,
      "rotation": 3
    },
    {
      "x": -23,
      "y": 0,
      "z": -21,
      "name": "Soil_Dirt"
    },
    {
      "x": -23,
      "y": 1,
      "z": -21,
      "name": "Rock_Volcanic"
    },
    {
      "x": -23,
      "y": 7,
      "z": -21,
      "name": "Factory_Roof_Steep",
      "rotation": 3
    },
    {
      "x": -23,
      "y": 8,
      "z": -21,
      "name": "Factory_Roof_Steep",
      "filler": 1024,
      "rotation": 3
    },
    {
      "x": -23,
      "y": 0,
      "z": -20,
      "name": "Soil_Dirt"
    },
    {
      "x": -23,
      "y": 1,
      "z": -20,
      "name": "Soil_Clay_Smooth_Black"
    },
    {
      "x": -23,
      "y": 7,
      "z": -20,
      "name": "Factory_Roof_Steep",
      "rotation": 3
    },
    {
      "x": -23,
      "y": 8,
      "z": -20,
      "name": "Factory_Roof_Steep",
      "filler": 1024,
      "rotation": 3
    },
    {
      "x": -23,
      "y": 0,
      "z": -19,
      "name": "Soil_Dirt"
    },
    {
      "x": -23,
      "y": 1,
      "z": -19,
      "name": "Soil_Clay_Smooth_Black"
    },
    {
      "x": -23,
      "y": 7,
      "z": -19,
      "name": "Factory_Roof_Steep",
      "rotation": 3
    },
    {
      "x": -23,
      "y": 8,
      "z": -19,
      "name": "Factory_Roof_Steep",
      "filler": 1024,
      "rotation": 3
    },
    {
      "x": -23,
      "y": 0,
      "z": -18,
      "name": "Soil_Dirt"
    },
    {
      "x": -23,
      "y": 1,
      "z": -18,
      "name": "Soil_Clay_Smooth_Black"
    },
    {
      "x": -23,
      "y": 7,
      "z": -18,
      "name": "Factory_Roof_Steep",
      "rotation": 3
    },
    {
      "x": -23,
      "y": 8,
      "z": -18,
      "name": "Factory_Roof_Steep",
      "filler": 1024,
      "rotation": 3
    },
    {
      "x": -23,
      "y": 0,
      "z": -17,
      "name": "Soil_Dirt"
    },
    {
      "x": -23,
      "y": 1,
      "z": -17,
      "name": "Rock_Volcanic_Half"
    },
    {
      "x": -23,
      "y": 7,
      "z": -17,
      "name": "Factory_Roof_Steep",
      "rotation": 3
    },
    {
      "x": -23,
      "y": 8,
      "z": -17,
      "name": "Factory_Roof_Steep",
      "filler": 1024,
      "rotation": 3
    },
    {
      "x": -23,
      "y": 0,
      "z": -16,
      "name": "Soil_Dirt"
    },
    {
      "x": -23,
      "y": 1,
      "z": -16,
      "name": "Rock_Volcanic_Half"
    },
    {
      "x": -23,
      "y": 7,
      "z": -16,
      "name": "Factory_Roof_Steep",
      "rotation": 3
    },
    {
      "x": -23,
      "y": 8,
      "z": -16,
      "name": "Factory_Roof_Steep",
      "filler": 1024,
      "rotation": 3
    },
    {
      "x": -23,
      "y": 0,
      "z": -15,
      "name": "Soil_Dirt"
    },
    {
      "x": -23,
      "y": 1,
      "z": -15,
      "name": "Rock_Volcanic_Half"
    },
    {
      "x": -23,
      "y": 7,
      "z": -15,
      "name": "Factory_Roof_Steep",
      "rotation": 3
    },
    {
      "x": -23,
      "y": 8,
      "z": -15,
      "name": "Factory_Roof_Steep",
      "filler": 1024,
      "rotation": 3
    },
    {
      "x": -23,
      "y": 0,
      "z": -14,
      "name": "Soil_Dirt"
    },
    {
      "x": -23,
      "y": 1,
      "z": -14,
      "name": "Soil_Clay_Smooth_Black"
    },
    {
      "x": -23,
      "y": 7,
      "z": -14,
      "name": "Factory_Roof_Steep",
      "rotation": 3
    },
    {
      "x": -23,
      "y": 8,
      "z": -14,
      "name": "Factory_Roof_Steep",
      "filler": 1024,
      "rotation": 3
    },
    {
      "x": -23,
      "y": 0,
      "z": -13,
      "name": "Soil_Dirt"
    },
    {
      "x": -23,
      "y": 1,
      "z": -13,
      "name": "Soil_Clay_Smooth_Black"
    },
    {
      "x": -23,
      "y": 7,
      "z": -13,
      "name": "Factory_Roof_Steep",
      "rotation": 3
    },
    {
      "x": -23,
      "y": 8,
      "z": -13,
      "name": "Factory_Roof_Steep",
      "filler": 1024,
      "rotation": 3
    },
    {
      "x": -23,
      "y": 0,
      "z": -12,
      "name": "Soil_Dirt"
    },
    {
      "x": -23,
      "y": 1,
      "z": -12,
      "name": "Rock_Volcanic_Half"
    },
    {
      "x": -23,
      "y": 7,
      "z": -12,
      "name": "Factory_Roof_Steep",
      "rotation": 3
    },
    {
      "x": -23,
      "y": 8,
      "z": -12,
      "name": "Factory_Roof_Steep",
      "filler": 1024,
      "rotation": 3
    },
    {
      "x": -23,
      "y": 0,
      "z": -11,
      "name": "Soil_Dirt"
    },
    {
      "x": -23,
      "y": 1,
      "z": -11,
      "name": "Soil_Clay_Smooth_Black"
    },
    {
      "x": -23,
      "y": 7,
      "z": -11,
      "name": "Factory_Roof_Steep",
      "rotation": 3
    },
    {
      "x": -23,
      "y": 8,
      "z": -11,
      "name": "Factory_Roof_Steep",
      "filler": 1024,
      "rotation": 3
    },
    {
      "x": -23,
      "y": 0,
      "z": -10,
      "name": "Soil_Dirt"
    },
    {
      "x": -23,
      "y": 1,
      "z": -10,
      "name": "Soil_Clay_Smooth_Black"
    },
    {
      "x": -23,
      "y": 7,
      "z": -10,
      "name": "Factory_Roof_Steep",
      "rotation": 3
    },
    {
      "x": -23,
      "y": 8,
      "z": -10,
      "name": "Factory_Roof_Steep",
      "filler": 1024,
      "rotation": 3
    },
    {
      "x": -23,
      "y": 0,
      "z": -9,
      "name": "Soil_Dirt"
    },
    {
      "x": -23,
      "y": 1,
      "z": -9,
      "name": "Soil_Clay_Smooth_Black"
    },
    {
      "x": -23,
      "y": 7,
      "z": -9,
      "name": "Factory_Roof_Steep",
      "rotation": 3
    },
    {
      "x": -23,
      "y": 8,
      "z": -9,
      "name": "Factory_Roof_Steep",
      "filler": 1024,
      "rotation": 3
    },
    {
      "x": -23,
      "y": 0,
      "z": -8,
      "name": "Soil_Dirt"
    },
    {
      "x": -23,
      "y": 1,
      "z": -8,
      "name": "Rock_Volcanic_Half"
    },
    {
      "x": -23,
      "y": 7,
      "z": -8,
      "name": "Factory_Roof_Steep",
      "rotation": 3
    },
    {
      "x": -23,
      "y": 8,
      "z": -8,
      "name": "Factory_Roof_Steep",
      "filler": 1024,
      "rotation": 3
    },
    {
      "x": -23,
      "y": 0,
      "z": -7,
      "name": "Soil_Dirt"
    },
    {
      "x": -23,
      "y": 1,
      "z": -7,
      "name": "Soil_Clay_Smooth_Black"
    },
    {
      "x": -23,
      "y": 7,
      "z": -7,
      "name": "Factory_Roof_Steep",
      "rotation": 3
    },
    {
      "x": -23,
      "y": 8,
      "z": -7,
      "name": "Factory_Roof_Steep",
      "filler": 1024,
      "rotation": 3
    },
    {
      "x": -23,
      "y": 0,
      "z": -6,
      "name": "Soil_Dirt"
    },
    {
      "x": -23,
      "y": 1,
      "z": -6,
      "name": "Soil_Clay_Smooth_Black"
    },
    {
      "x": -23,
      "y": 7,
      "z": -6,
      "name": "Factory_Roof_Steep",
      "rotation": 3
    },
    {
      "x": -23,
      "y": 8,
      "z": -6,
      "name": "Factory_Roof_Steep",
      "filler": 1024,
      "rotation": 3
    },
    {
      "x": -23,
      "y": 0,
      "z": -5,
      "name": "Soil_Dirt"
    },
    {
      "x": -23,
      "y": 1,
      "z": -5,
      "name": "Rock_Volcanic_Half"
    },
    {
      "x": -23,
      "y": 7,
      "z": -5,
      "name": "Factory_Roof_Steep",
      "rotation": 3
    },
    {
      "x": -23,
      "y": 8,
      "z": -5,
      "name": "Factory_Roof_Steep",
      "filler": 1024,
      "rotation": 3
    },
    {
      "x": -23,
      "y": 0,
      "z": -4,
      "name": "Soil_Dirt"
    },
    {
      "x": -23,
      "y": 1,
      "z": -4,
      "name": "Rock_Volcanic_Half"
    },
    {
      "x": -23,
      "y": 7,
      "z": -4,
      "name": "Factory_Roof_Steep",
      "rotation": 3
    },
    {
      "x": -23,
      "y": 8,
      "z": -4,
      "name": "Factory_Roof_Steep",
      "filler": 1024,
      "rotation": 3
    },
    {
      "x": -23,
      "y": 0,
      "z": -3,
      "name": "Soil_Dirt"
    },
    {
      "x": -23,
      "y": 1,
      "z": -3,
      "name": "Rock_Volcanic"
    },
    {
      "x": -23,
      "y": 7,
      "z": -3,
      "name": "Factory_Roof_Steep",
      "rotation": 3
    },
    {
      "x": -23,
      "y": 8,
      "z": -3,
      "name": "Factory_Roof_Steep",
      "filler": 1024,
      "rotation": 3
    },
    {
      "x": -23,
      "y": 0,
      "z": -2,
      "name": "Soil_Dirt"
    },
    {
      "x": -23,
      "y": 1,
      "z": -2,
      "name": "Rock_Volcanic"
    },
    {
      "x": -23,
      "y": 7,
      "z": -2,
      "name": "Factory_Roof_Steep",
      "rotation": 3
    },
    {
      "x": -23,
      "y": 8,
      "z": -2,
      "name": "Factory_Roof_Steep",
      "filler": 1024,
      "rotation": 3
    },
    {
      "x": -23,
      "y": 0,
      "z": -1,
      "name": "Soil_Dirt"
    },
    {
      "x": -23,
      "y": 1,
      "z": -1,
      "name": "Rock_Volcanic_Half"
    },
    {
      "x": -23,
      "y": 7,
      "z": -1,
      "name": "Factory_Roof_Steep",
      "rotation": 3
    },
    {
      "x": -23,
      "y": 8,
      "z": -1,
      "name": "Factory_Roof_Steep",
      "filler": 1024,
      "rotation": 3
    },
    {
      "x": -23,
      "y": 0,
      "z": 0,
      "name": "Soil_Dirt"
    },
    {
      "x": -23,
      "y": 1,
      "z": 0,
      "name": "Rock_Volcanic"
    },
    {
      "x": -23,
      "y": 0,
      "z": 1,
      "name": "Soil_Dirt"
    },
    {
      "x": -23,
      "y": 1,
      "z": 1,
      "name": "Soil_Clay_Smooth_Black"
    },
    {
      "x": -23,
      "y": 7,
      "z": 1,
      "name": "Factory_Roof_Steep",
      "rotation": 3
    },
    {
      "x": -23,
      "y": 8,
      "z": 1,
      "name": "Factory_Roof_Steep",
      "filler": 1024,
      "rotation": 3
    },
    {
      "x": -23,
      "y": 0,
      "z": 2,
      "name": "Soil_Dirt"
    },
    {
      "x": -23,
      "y": 1,
      "z": 2,
      "name": "Rock_Volcanic_Half"
    },
    {
      "x": -23,
      "y": 7,
      "z": 2,
      "name": "Factory_Roof_Steep",
      "rotation": 3
    },
    {
      "x": -23,
      "y": 8,
      "z": 2,
      "name": "Factory_Roof_Steep",
      "filler": 1024,
      "rotation": 3
    },
    {
      "x": -23,
      "y": 0,
      "z": 3,
      "name": "Soil_Dirt"
    },
    {
      "x": -23,
      "y": 1,
      "z": 3,
      "name": "Soil_Clay_Smooth_Black"
    },
    {
      "x": -23,
      "y": 2,
      "z": 3,
      "name": "Rock_Volcanic_Brick_Smooth"
    },
    {
      "x": -23,
      "y": 7,
      "z": 3,
      "name": "Factory_Roof_Steep",
      "rotation": 3
    },
    {
      "x": -23,
      "y": 8,
      "z": 3,
      "name": "Factory_Roof_Steep",
      "filler": 1024,
      "rotation": 3
    },
    {
      "x": -23,
      "y": 0,
      "z": 4,
      "name": "Soil_Dirt"
    },
    {
      "x": -23,
      "y": 1,
      "z": 4,
      "name": "Soil_Clay_Smooth_Black"
    },
    {
      "x": -23,
      "y": 7,
      "z": 4,
      "name": "Factory_Roof_Steep",
      "rotation": 3
    },
    {
      "x": -23,
      "y": 8,
      "z": 4,
      "name": "Factory_Roof_Steep",
      "filler": 1024,
      "rotation": 3
    },
    {
      "x": -23,
      "y": 0,
      "z": 5,
      "name": "Soil_Dirt"
    },
    {
      "x": -23,
      "y": 1,
      "z": 5,
      "name": "Soil_Clay_Smooth_Black"
    },
    {
      "x": -23,
      "y": 7,
      "z": 5,
      "name": "Factory_Roof_Steep",
      "rotation": 3
    },
    {
      "x": -23,
      "y": 8,
      "z": 5,
      "name": "Factory_Roof_Steep",
      "filler": 1024,
      "rotation": 3
    },
    {
      "x": -23,
      "y": 0,
      "z": 6,
      "name": "Soil_Dirt"
    },
    {
      "x": -23,
      "y": 1,
      "z": 6,
      "name": "Rock_Volcanic_Half"
    },
    {
      "x": -23,
      "y": 0,
      "z": 7,
      "name": "Soil_Dirt"
    },
    {
      "x": -23,
      "y": 1,
      "z": 7,
      "name": "Soil_Clay_Smooth_Black"
    },
    {
      "x": -23,
      "y": 0,
      "z": 8,
      "name": "Soil_Dirt"
    },
    {
      "x": -23,
      "y": 1,
      "z": 8,
      "name": "Soil_Clay_Smooth_Black"
    },
    {
      "x": -23,
      "y": 2,
      "z": 8,
      "name": "Factory_Fence_L",
      "filler": 31
    },
    {
      "x": -23,
      "y": 3,
      "z": 8,
      "name": "Factory_Fence_L",
      "filler": 1055
    },
    {
      "x": -23,
      "y": 5,
      "z": 8,
      "name": "Deco_Iron_Bars"
    },
    {
      "x": -23,
      "y": 0,
      "z": 9,
      "name": "Soil_Dirt"
    },
    {
      "x": -23,
      "y": 0,
      "z": 10,
      "name": "Soil_Dirt"
    },
    {
      "x": -23,
      "y": 0,
      "z": 11,
      "name": "Soil_Dirt"
    },
    {
      "x": -23,
      "y": 0,
      "z": 12,
      "name": "Soil_Dirt"
    },
    {
      "x": -23,
      "y": 0,
      "z": 13,
      "name": "Soil_Dirt"
    },
    {
      "x": -23,
      "y": 0,
      "z": 14,
      "name": "Soil_Dirt"
    },
    {
      "x": -23,
      "y": 0,
      "z": 15,
      "name": "Soil_Dirt"
    },
    {
      "x": -23,
      "y": 0,
      "z": 16,
      "name": "Soil_Dirt"
    },
    {
      "x": -23,
      "y": 0,
      "z": 17,
      "name": "Soil_Dirt"
    },
    {
      "x": -23,
      "y": 0,
      "z": 18,
      "name": "Soil_Dirt"
    },
    {
      "x": -23,
      "y": 0,
      "z": 19,
      "name": "Soil_Dirt"
    },
    {
      "x": -22,
      "y": 0,
      "z": -26,
      "name": "Soil_Dirt"
    },
    {
      "x": -22,
      "y": 0,
      "z": -25,
      "name": "Soil_Dirt"
    },
    {
      "x": -22,
      "y": 1,
      "z": -25,
      "name": "Soil_Clay_Smooth_Black"
    },
    {
      "x": -22,
      "y": 2,
      "z": -25,
      "name": "Rock_Volcanic_Brick_Smooth"
    },
    {
      "x": -22,
      "y": 3,
      "z": -25,
      "name": "Rock_Volcanic_Brick_Smooth"
    },
    {
      "x": -22,
      "y": 4,
      "z": -25,
      "name": "Deco_Iron_Bars"
    },
    {
      "x": -22,
      "y": 0,
      "z": -24,
      "name": "Soil_Dirt"
    },
    {
      "x": -22,
      "y": 1,
      "z": -24,
      "name": "Soil_Clay_Smooth_Black"
    },
    {
      "x": -22,
      "y": 0,
      "z": -23,
      "name": "Soil_Dirt"
    },
    {
      "x": -22,
      "y": 1,
      "z": -23,
      "name": "Rock_Volcanic_Half"
    },
    {
      "x": -22,
      "y": 9,
      "z": -23,
      "name": "Factory_Roof_Hollow",
      "rotation": 3
    },
    {
      "x": -22,
      "y": 0,
      "z": -22,
      "name": "Soil_Dirt"
    },
    {
      "x": -22,
      "y": 1,
      "z": -22,
      "name": "Rock_Volcanic_Half"
    },
    {
      "x": -22,
      "y": 2,
      "z": -22,
      "name": "Metal_Plate_Pillar_Base_Rusted"
    },
    {
      "x": -22,
      "y": 3,
      "z": -22,
      "name": "Metal_Plate_Pillar_Middle_Rusted"
    },
    {
      "x": -22,
      "y": 4,
      "z": -22,
      "name": "Metal_Plate_Pillar_Middle_Rusted"
    },
    {
      "x": -22,
      "y": 5,
      "z": -22,
      "name": "Metal_Plate_Pillar_Middle_Rusted"
    },
    {
      "x": -22,
      "y": 6,
      "z": -22,
      "name": "Metal_Plate_Pillar_Base_Rusted",
      "rotation": 8
    },
    {
      "x": -22,
      "y": 7,
      "z": -22,
      "name": "Rock_Volcanic_Brick"
    },
    {
      "x": -22,
      "y": 9,
      "z": -22,
      "name": "Factory_Roof_Hollow",
      "rotation": 3
    },
    {
      "x": -22,
      "y": 0,
      "z": -21,
      "name": "Soil_Dirt"
    },
    {
      "x": -22,
      "y": 1,
      "z": -21,
      "name": "Soil_Clay_Smooth_Black"
    },
    {
      "x": -22,
      "y": 2,
      "z": -21,
      "name": "Factory_Bricks"
    },
    {
      "x": -22,
      "y": 3,
      "z": -21,
      "name": "Factory_Bricks"
    },
    {
      "x": -22,
      "y": 4,
      "z": -21,
      "name": "Rock_Volcanic_Brick",
      "rotation": 1
    },
    {
      "x": -22,
      "y": 5,
      "z": -21,
      "name": "Rock_Volcanic_Brick_Ornate",
      "rotation": 1
    },
    {
      "x": -22,
      "y": 6,
      "z": -21,
      "name": "Rock_Volcanic_Brick_Smooth"
    },
    {
      "x": -22,
      "y": 7,
      "z": -21,
      "name": "Rock_Volcanic_Brick"
    },
    {
      "x": -22,
      "y": 8,
      "z": -21,
      "name": "Rock_Volcanic_Brick"
    },
    {
      "x": -22,
      "y": 0,
      "z": -20,
      "name": "Soil_Dirt"
    },
    {
      "x": -22,
      "y": 1,
      "z": -20,
      "name": "Rock_Volcanic_Half"
    },
    {
      "x": -22,
      "y": 2,
      "z": -20,
      "name": "Factory_Bricks"
    },
    {
      "x": -22,
      "y": 3,
      "z": -20,
      "name": "Factory_Bricks"
    },
    {
      "x": -22,
      "y": 4,
      "z": -20,
      "name": "Rock_Volcanic_Brick_Smooth",
      "rotation": 1
    },
    {
      "x": -22,
      "y": 5,
      "z": -20,
      "name": "Rock_Volcanic_Brick",
      "rotation": 1
    },
    {
      "x": -22,
      "y": 6,
      "z": -20,
      "name": "Rock_Volcanic_Brick_Ornate"
    },
    {
      "x": -22,
      "y": 7,
      "z": -20,
      "name": "Rock_Volcanic_Brick"
    },
    {
      "x": -22,
      "y": 8,
      "z": -20,
      "name": "Rock_Volcanic_Brick"
    },
    {
      "x": -22,
      "y": 0,
      "z": -19,
      "name": "Soil_Dirt"
    },
    {
      "x": -22,
      "y": 1,
      "z": -19,
      "name": "Rock_Volcanic"
    },
    {
      "x": -22,
      "y": 2,
      "z": -19,
      "name": "Factory_Bricks"
    },
    {
      "x": -22,
      "y": 3,
      "z": -19,
      "name": "Factory_Bricks"
    },
    {
      "x": -22,
      "y": 4,
      "z": -19,
      "name": "Rock_Volcanic_Brick",
      "rotation": 1
    },
    {
      "x": -22,
      "y": 5,
      "z": -19,
      "name": "Rock_Volcanic_Brick_Smooth",
      "rotation": 1
    },
    {
      "x": -22,
      "y": 6,
      "z": -19,
      "name": "Rock_Volcanic_Brick_Ornate"
    },
    {
      "x": -22,
      "y": 7,
      "z": -19,
      "name": "Rock_Volcanic_Brick_Smooth"
    },
    {
      "x": -22,
      "y": 9,
      "z": -19,
      "name": "Factory_Roof_Hollow",
      "rotation": 3
    },
    {
      "x": -22,
      "y": 0,
      "z": -18,
      "name": "Soil_Dirt"
    },
    {
      "x": -22,
      "y": 1,
      "z": -18,
      "name": "Soil_Clay_Smooth_Black"
    },
    {
      "x": -22,
      "y": 2,
      "z": -18,
      "name": "Factory_Bricks"
    },
    {
      "x": -22,
      "y": 3,
      "z": -18,
      "name": "Factory_Bricks"
    },
    {
      "x": -22,
      "y": 5,
      "z": -18,
      "name": "Rock_Volcanic_Brick_Ornate",
      "rotation": 1
    },
    {
      "x": -22,
      "y": 6,
      "z": -18,
      "name": "Rock_Volcanic_Brick_Smooth"
    },
    {
      "x": -22,
      "y": 7,
      "z": -18,
      "name": "Rock_Volcanic_Brick"
    },
    {
      "x": -22,
      "y": 9,
      "z": -18,
      "name": "Factory_Roof_Hollow",
      "rotation": 3
    },
    {
      "x": -22,
      "y": 0,
      "z": -17,
      "name": "Soil_Dirt"
    },
    {
      "x": -22,
      "y": 1,
      "z": -17,
      "name": "Rock_Volcanic_Half"
    },
    {
      "x": -22,
      "y": 2,
      "z": -17,
      "name": "Factory_Bricks"
    },
    {
      "x": -22,
      "y": 3,
      "z": -17,
      "name": "Factory_Bricks"
    },
    {
      "x": -22,
      "y": 4,
      "z": -17,
      "name": "Rock_Volcanic_Brick",
      "rotation": 1
    },
    {
      "x": -22,
      "y": 5,
      "z": -17,
      "name": "Rock_Volcanic_Brick_Ornate",
      "rotation": 1
    },
    {
      "x": -22,
      "y": 6,
      "z": -17,
      "name": "Rock_Volcanic_Brick_Smooth"
    },
    {
      "x": -22,
      "y": 9,
      "z": -17,
      "name": "Factory_Roof_Hollow",
      "rotation": 3
    },
    {
      "x": -22,
      "y": 0,
      "z": -16,
      "name": "Soil_Dirt"
    },
    {
      "x": -22,
      "y": 1,
      "z": -16,
      "name": "Rock_Volcanic_Half"
    },
    {
      "x": -22,
      "y": 2,
      "z": -16,
      "name": "Factory_Bricks"
    },
    {
      "x": -22,
      "y": 3,
      "z": -16,
      "name": "Factory_Bricks"
    },
    {
      "x": -22,
      "y": 4,
      "z": -16,
      "name": "Rock_Volcanic_Brick",
      "rotation": 1
    },
    {
      "x": -22,
      "y": 5,
      "z": -16,
      "name": "Rock_Volcanic_Brick",
      "rotation": 1
    },
    {
      "x": -22,
      "y": 6,
      "z": -16,
      "name": "Rock_Volcanic_Brick_Smooth"
    },
    {
      "x": -22,
      "y": 7,
      "z": -16,
      "name": "Rock_Volcanic_Brick_Smooth"
    },
    {
      "x": -22,
      "y": 0,
      "z": -15,
      "name": "Soil_Dirt"
    },
    {
      "x": -22,
      "y": 1,
      "z": -15,
      "name": "Soil_Clay_Smooth_Black"
    },
    {
      "x": -22,
      "y": 2,
      "z": -15,
      "name": "Factory_Bricks"
    },
    {
      "x": -22,
      "y": 3,
      "z": -15,
      "name": "Factory_Bricks"
    },
    {
      "x": -22,
      "y": 4,
      "z": -15,
      "name": "Rock_Volcanic_Brick_Ornate",
      "rotation": 1
    },
    {
      "x": -22,
      "y": 5,
      "z": -15,
      "name": "Rock_Volcanic_Brick_Ornate",
      "rotation": 1
    },
    {
      "x": -22,
      "y": 6,
      "z": -15,
      "name": "Rock_Volcanic_Brick"
    },
    {
      "x": -22,
      "y": 7,
      "z": -15,
      "name": "Rock_Volcanic_Brick"
    },
    {
      "x": -22,
      "y": 9,
      "z": -15,
      "name": "Factory_Roof_Hollow",
      "rotation": 3
    },
    {
      "x": -22,
      "y": 0,
      "z": -14,
      "name": "Soil_Dirt"
    },
    {
      "x": -22,
      "y": 1,
      "z": -14,
      "name": "Soil_Clay_Smooth_Black"
    },
    {
      "x": -22,
      "y": 2,
      "z": -14,
      "name": "Factory_Bricks"
    },
    {
      "x": -22,
      "y": 3,
      "z": -14,
      "name": "Factory_Bricks"
    },
    {
      "x": -22,
      "y": 4,
      "z": -14,
      "name": "Rock_Volcanic_Brick_Ornate",
      "rotation": 1
    },
    {
      "x": -22,
      "y": 5,
      "z": -14,
      "name": "Rock_Volcanic_Brick",
      "rotation": 1
    },
    {
      "x": -22,
      "y": 6,
      "z": -14,
      "name": "Rock_Volcanic_Brick"
    },
    {
      "x": -22,
      "y": 7,
      "z": -14,
      "name": "Rock_Volcanic_Brick_Smooth"
    },
    {
      "x": -22,
      "y": 9,
      "z": -14,
      "name": "Factory_Roof_Hollow",
      "rotation": 3
    },
    {
      "x": -22,
      "y": 0,
      "z": -13,
      "name": "Soil_Dirt"
    },
    {
      "x": -22,
      "y": 1,
      "z": -13,
      "name": "Rock_Volcanic_Half"
    },
    {
      "x": -22,
      "y": 2,
      "z": -13,
      "name": "Factory_Bricks"
    },
    {
      "x": -22,
      "y": 3,
      "z": -13,
      "name": "Factory_Bricks"
    },
    {
      "x": -22,
      "y": 4,
      "z": -13,
      "name": "Rock_Volcanic_Brick_Smooth",
      "rotation": 1
    },
    {
      "x": -22,
      "y": 5,
      "z": -13,
      "name": "Rock_Volcanic_Brick",
      "rotation": 1
    },
    {
      "x": -22,
      "y": 6,
      "z": -13,
      "name": "Rock_Volcanic_Brick_Smooth"
    },
    {
      "x": -22,
      "y": 9,
      "z": -13,
      "name": "Factory_Roof_Hollow",
      "rotation": 3
    },
    {
      "x": -22,
      "y": 0,
      "z": -12,
      "name": "Soil_Dirt"
    },
    {
      "x": -22,
      "y": 1,
      "z": -12,
      "name": "Rock_Volcanic_Half"
    },
    {
      "x": -22,
      "y": 2,
      "z": -12,
      "name": "Factory_Bricks"
    },
    {
      "x": -22,
      "y": 3,
      "z": -12,
      "name": "Factory_Bricks"
    },
    {
      "x": -22,
      "y": 4,
      "z": -12,
      "name": "Rock_Volcanic_Brick",
      "rotation": 1
    },
    {
      "x": -22,
      "y": 5,
      "z": -12,
      "name": "Rock_Volcanic_Brick_Smooth",
      "rotation": 1
    },
    {
      "x": -22,
      "y": 6,
      "z": -12,
      "name": "Rock_Volcanic_Brick_Ornate"
    },
    {
      "x": -22,
      "y": 7,
      "z": -12,
      "name": "Rock_Volcanic_Brick_Smooth"
    },
    {
      "x": -22,
      "y": 9,
      "z": -12,
      "name": "Factory_Roof_Hollow",
      "rotation": 3
    },
    {
      "x": -22,
      "y": 0,
      "z": -11,
      "name": "Soil_Dirt"
    },
    {
      "x": -22,
      "y": 1,
      "z": -11,
      "name": "Soil_Clay_Smooth_Black"
    },
    {
      "x": -22,
      "y": 2,
      "z": -11,
      "name": "Factory_Bricks"
    },
    {
      "x": -22,
      "y": 3,
      "z": -11,
      "name": "Factory_Bricks"
    },
    {
      "x": -22,
      "y": 5,
      "z": -11,
      "name": "Rock_Volcanic_Brick",
      "rotation": 1
    },
    {
      "x": -22,
      "y": 6,
      "z": -11,
      "name": "Rock_Volcanic_Brick"
    },
    {
      "x": -22,
      "y": 7,
      "z": -11,
      "name": "Rock_Volcanic_Brick"
    },
    {
      "x": -22,
      "y": 8,
      "z": -11,
      "name": "Rock_Volcanic_Brick"
    },
    {
      "x": -22,
      "y": 0,
      "z": -10,
      "name": "Soil_Dirt"
    },
    {
      "x": -22,
      "y": 1,
      "z": -10,
      "name": "Rock_Volcanic_Half"
    },
    {
      "x": -22,
      "y": 2,
      "z": -10,
      "name": "Factory_Bricks"
    },
    {
      "x": -22,
      "y": 3,
      "z": -10,
      "name": "Factory_Bricks"
    },
    {
      "x": -22,
      "y": 4,
      "z": -10,
      "name": "Rock_Volcanic_Brick_Smooth",
      "rotation": 1
    },
    {
      "x": -22,
      "y": 5,
      "z": -10,
      "name": "Rock_Volcanic_Brick",
      "rotation": 1
    },
    {
      "x": -22,
      "y": 6,
      "z": -10,
      "name": "Rock_Volcanic_Brick"
    },
    {
      "x": -22,
      "y": 7,
      "z": -10,
      "name": "Rock_Volcanic_Brick_Ornate"
    },
    {
      "x": -22,
      "y": 0,
      "z": -9,
      "name": "Soil_Dirt"
    },
    {
      "x": -22,
      "y": 1,
      "z": -9,
      "name": "Rock_Volcanic"
    },
    {
      "x": -22,
      "y": 2,
      "z": -9,
      "name": "Factory_Bricks"
    },
    {
      "x": -22,
      "y": 3,
      "z": -9,
      "name": "Factory_Bricks"
    },
    {
      "x": -22,
      "y": 4,
      "z": -9,
      "name": "Rock_Volcanic_Brick",
      "rotation": 3
    },
    {
      "x": -22,
      "y": 5,
      "z": -9,
      "name": "Rock_Volcanic_Brick",
      "rotation": 3
    },
    {
      "x": -22,
      "y": 6,
      "z": -9,
      "name": "Rock_Volcanic_Brick_Smooth"
    },
    {
      "x": -22,
      "y": 7,
      "z": -9,
      "name": "Rock_Volcanic_Brick_Smooth"
    },
    {
      "x": -22,
      "y": 8,
      "z": -9,
      "name": "Rock_Volcanic_Brick_Smooth"
    },
    {
      "x": -22,
      "y": 0,
      "z": -8,
      "name": "Soil_Dirt"
    },
    {
      "x": -22,
      "y": 1,
      "z": -8,
      "name": "Soil_Clay_Smooth_Black"
    },
    {
      "x": -22,
      "y": 2,
      "z": -8,
      "name": "Factory_Bricks"
    },
    {
      "x": -22,
      "y": 3,
      "z": -8,
      "name": "Factory_Bricks"
    },
    {
      "x": -22,
      "y": 4,
      "z": -8,
      "name": "Rock_Volcanic_Brick",
      "rotation": 3
    },
    {
      "x": -22,
      "y": 5,
      "z": -8,
      "name": "Rock_Volcanic_Brick"
    },
    {
      "x": -22,
      "y": 6,
      "z": -8,
      "name": "Rock_Volcanic_Brick_Smooth"
    },
    {
      "x": -22,
      "y": 7,
      "z": -8,
      "name": "Rock_Volcanic_Brick"
    },
    {
      "x": -22,
      "y": 8,
      "z": -8,
      "name": "Rock_Volcanic_Brick"
    },
    {
      "x": -22,
      "y": 0,
      "z": -7,
      "name": "Soil_Dirt"
    },
    {
      "x": -22,
      "y": 1,
      "z": -7,
      "name": "Soil_Clay_Smooth_Black"
    },
    {
      "x": -22,
      "y": 2,
      "z": -7,
      "name": "Factory_Bricks"
    },
    {
      "x": -22,
      "y": 3,
      "z": -7,
      "name": "Factory_Bricks"
    },
    {
      "x": -22,
      "y": 4,
      "z": -7,
      "name": "Rock_Volcanic_Brick",
      "rotation": 3
    },
    {
      "x": -22,
      "y": 5,
      "z": -7,
      "name": "Rock_Volcanic_Brick",
      "rotation": 3
    },
    {
      "x": -22,
      "y": 6,
      "z": -7,
      "name": "Rock_Volcanic_Brick"
    },
    {
      "x": -22,
      "y": 7,
      "z": -7,
      "name": "Rock_Volcanic_Brick"
    },
    {
      "x": -22,
      "y": 8,
      "z": -7,
      "name": "Rock_Volcanic_Brick_Smooth"
    },
    {
      "x": -22,
      "y": 0,
      "z": -6,
      "name": "Soil_Dirt"
    },
    {
      "x": -22,
      "y": 1,
      "z": -6,
      "name": "Rock_Volcanic_Half"
    },
    {
      "x": -22,
      "y": 2,
      "z": -6,
      "name": "Factory_Bricks"
    },
    {
      "x": -22,
      "y": 3,
      "z": -6,
      "name": "Factory_Bricks"
    },
    {
      "x": -22,
      "y": 4,
      "z": -6,
      "name": "Rock_Volcanic_Brick_Smooth",
      "rotation": 3
    },
    {
      "x": -22,
      "y": 5,
      "z": -6,
      "name": "Rock_Volcanic_Brick_Smooth",
      "rotation": 3
    },
    {
      "x": -22,
      "y": 6,
      "z": -6,
      "name": "Rock_Volcanic_Brick"
    },
    {
      "x": -22,
      "y": 7,
      "z": -6,
      "name": "Rock_Volcanic_Brick"
    },
    {
      "x": -22,
      "y": 9,
      "z": -6,
      "name": "Factory_Roof_Hollow",
      "rotation": 3
    },
    {
      "x": -22,
      "y": 0,
      "z": -5,
      "name": "Soil_Dirt"
    },
    {
      "x": -22,
      "y": 1,
      "z": -5,
      "name": "Rock_Volcanic"
    },
    {
      "x": -22,
      "y": 2,
      "z": -5,
      "name": "Factory_Bricks"
    },
    {
      "x": -22,
      "y": 3,
      "z": -5,
      "name": "Factory_Bricks"
    },
    {
      "x": -22,
      "y": 4,
      "z": -5,
      "name": "Rock_Volcanic_Brick_Smooth",
      "rotation": 3
    },
    {
      "x": -22,
      "y": 5,
      "z": -5,
      "name": "Rock_Volcanic_Brick_Ornate",
      "rotation": 3
    },
    {
      "x": -22,
      "y": 6,
      "z": -5,
      "name": "Rock_Volcanic_Brick_Smooth"
    },
    {
      "x": -22,
      "y": 7,
      "z": -5,
      "name": "Rock_Volcanic_Brick"
    },
    {
      "x": -22,
      "y": 9,
      "z": -5,
      "name": "Factory_Roof_Hollow",
      "rotation": 3
    },
    {
      "x": -22,
      "y": 0,
      "z": -4,
      "name": "Soil_Dirt"
    },
    {
      "x": -22,
      "y": 1,
      "z": -4,
      "name": "Rock_Volcanic_Half"
    },
    {
      "x": -22,
      "y": 2,
      "z": -4,
      "name": "Factory_Bricks"
    },
    {
      "x": -22,
      "y": 3,
      "z": -4,
      "name": "Factory_Bricks"
    },
    {
      "x": -22,
      "y": 4,
      "z": -4,
      "name": "Rock_Volcanic_Brick",
      "rotation": 3
    },
    {
      "x": -22,
      "y": 5,
      "z": -4,
      "name": "Rock_Volcanic_Brick",
      "rotation": 3
    },
    {
      "x": -22,
      "y": 6,
      "z": -4,
      "name": "Rock_Volcanic_Brick_Smooth"
    },
    {
      "x": -22,
      "y": 7,
      "z": -4,
      "name": "Rock_Volcanic_Brick_Smooth"
    },
    {
      "x": -22,
      "y": 9,
      "z": -4,
      "name": "Factory_Roof_Hollow",
      "rotation": 3
    },
    {
      "x": -22,
      "y": 0,
      "z": -3,
      "name": "Soil_Dirt"
    },
    {
      "x": -22,
      "y": 1,
      "z": -3,
      "name": "Soil_Clay_Smooth_Black"
    },
    {
      "x": -22,
      "y": 2,
      "z": -3,
      "name": "Factory_Bricks"
    },
    {
      "x": -22,
      "y": 3,
      "z": -3,
      "name": "Factory_Bricks"
    },
    {
      "x": -22,
      "y": 4,
      "z": -3,
      "name": "Rock_Volcanic_Brick",
      "rotation": 3
    },
    {
      "x": -22,
      "y": 5,
      "z": -3,
      "name": "Rock_Volcanic_Brick_Smooth",
      "rotation": 3
    },
    {
      "x": -22,
      "y": 6,
      "z": -3,
      "name": "Rock_Volcanic_Brick"
    },
    {
      "x": -22,
      "y": 7,
      "z": -3,
      "name": "Rock_Volcanic_Brick"
    },
    {
      "x": -22,
      "y": 9,
      "z": -3,
      "name": "Factory_Roof_Hollow",
      "rotation": 3
    },
    {
      "x": -22,
      "y": 0,
      "z": -2,
      "name": "Soil_Dirt"
    },
    {
      "x": -22,
      "y": 1,
      "z": -2,
      "name": "Soil_Clay_Smooth_Black"
    },
    {
      "x": -22,
      "y": 2,
      "z": -2,
      "name": "Factory_Bricks"
    },
    {
      "x": -22,
      "y": 3,
      "z": -2,
      "name": "Factory_Bricks"
    },
    {
      "x": -22,
      "y": 4,
      "z": -2,
      "name": "Rock_Volcanic_Brick_Smooth",
      "rotation": 3
    },
    {
      "x": -22,
      "y": 5,
      "z": -2,
      "name": "Rock_Volcanic_Brick_Smooth",
      "rotation": 3
    },
    {
      "x": -22,
      "y": 6,
      "z": -2,
      "name": "Rock_Volcanic_Brick"
    },
    {
      "x": -22,
      "y": 7,
      "z": -2,
      "name": "Rock_Volcanic_Brick"
    },
    {
      "x": -22,
      "y": 8,
      "z": -2,
      "name": "Rock_Volcanic_Brick"
    },
    {
      "x": -22,
      "y": 9,
      "z": -2,
      "name": "Factory_Roof",
      "rotation": 3
    },
    {
      "x": -22,
      "y": 0,
      "z": -1,
      "name": "Soil_Dirt"
    },
    {
      "x": -22,
      "y": 1,
      "z": -1,
      "name": "Rock_Volcanic_Half"
    },
    {
      "x": -22,
      "y": 2,
      "z": -1,
      "name": "Factory_Bricks"
    },
    {
      "x": -22,
      "y": 3,
      "z": -1,
      "name": "Factory_Bricks"
    },
    {
      "x": -22,
      "y": 4,
      "z": -1,
      "name": "Rock_Volcanic_Brick",
      "rotation": 3
    },
    {
      "x": -22,
      "y": 5,
      "z": -1,
      "name": "Rock_Volcanic_Brick",
      "rotation": 3
    },
    {
      "x": -22,
      "y": 6,
      "z": -1,
      "name": "Rock_Volcanic_Brick"
    },
    {
      "x": -22,
      "y": 7,
      "z": -1,
      "name": "Rock_Volcanic_Brick"
    },
    {
      "x": -22,
      "y": 8,
      "z": -1,
      "name": "Rock_Volcanic_Brick_Ornate"
    },
    {
      "x": -22,
      "y": 9,
      "z": -1,
      "name": "Factory_Roof",
      "rotation": 3
    },
    {
      "x": -22,
      "y": 0,
      "z": 0,
      "name": "Soil_Dirt"
    },
    {
      "x": -22,
      "y": 1,
      "z": 0,
      "name": "Rock_Volcanic"
    },
    {
      "x": -22,
      "y": 2,
      "z": 0,
      "name": "Factory_Bricks"
    },
    {
      "x": -22,
      "y": 3,
      "z": 0,
      "name": "Factory_Bricks"
    },
    {
      "x": -22,
      "y": 4,
      "z": 0,
      "name": "Rock_Volcanic_Brick",
      "rotation": 3
    },
    {
      "x": -22,
      "y": 5,
      "z": 0,
      "name": "Rock_Volcanic_Brick_Smooth",
      "rotation": 3
    },
    {
      "x": -22,
      "y": 6,
      "z": 0,
      "name": "Rock_Volcanic_Brick_Smooth"
    },
    {
      "x": -22,
      "y": 7,
      "z": 0,
      "name": "Rock_Volcanic_Brick_Smooth"
    },
    {
      "x": -22,
      "y": 8,
      "z": 0,
      "name": "Rock_Volcanic_Brick"
    },
    {
      "x": -22,
      "y": 0,
      "z": 1,
      "name": "Soil_Dirt"
    },
    {
      "x": -22,
      "y": 1,
      "z": 1,
      "name": "Soil_Clay_Smooth_Black"
    },
    {
      "x": -22,
      "y": 2,
      "z": 1,
      "name": "Factory_Bricks"
    },
    {
      "x": -22,
      "y": 3,
      "z": 1,
      "name": "Factory_Bricks"
    },
    {
      "x": -22,
      "y": 4,
      "z": 1,
      "name": "Rock_Volcanic_Brick",
      "rotation": 3
    },
    {
      "x": -22,
      "y": 5,
      "z": 1,
      "name": "Rock_Volcanic_Brick_Smooth",
      "rotation": 3
    },
    {
      "x": -22,
      "y": 6,
      "z": 1,
      "name": "Rock_Volcanic_Brick"
    },
    {
      "x": -22,
      "y": 7,
      "z": 1,
      "name": "Rock_Volcanic_Brick_Smooth"
    },
    {
      "x": -22,
      "y": 9,
      "z": 1,
      "name": "Factory_Roof_Hollow",
      "rotation": 3
    },
    {
      "x": -22,
      "y": 0,
      "z": 2,
      "name": "Soil_Dirt"
    },
    {
      "x": -22,
      "y": 1,
      "z": 2,
      "name": "Rock_Volcanic_Half"
    },
    {
      "x": -22,
      "y": 2,
      "z": 2,
      "name": "Factory_Bricks"
    },
    {
      "x": -22,
      "y": 3,
      "z": 2,
      "name": "Factory_Bricks"
    },
    {
      "x": -22,
      "y": 4,
      "z": 2,
      "name": "Rock_Volcanic_Brick_Ornate",
      "rotation": 3
    },
    {
      "x": -22,
      "y": 5,
      "z": 2,
      "name": "Rock_Volcanic_Brick_Smooth",
      "rotation": 3
    },
    {
      "x": -22,
      "y": 6,
      "z": 2,
      "name": "Rock_Volcanic_Brick"
    },
    {
      "x": -22,
      "y": 7,
      "z": 2,
      "name": "Rock_Volcanic_Brick"
    },
    {
      "x": -22,
      "y": 8,
      "z": 2,
      "name": "Rock_Volcanic_Brick_Smooth"
    },
    {
      "x": -22,
      "y": 9,
      "z": 2,
      "name": "Factory_Roof_Hollow",
      "rotation": 3
    },
    {
      "x": -22,
      "y": 0,
      "z": 3,
      "name": "Soil_Dirt"
    },
    {
      "x": -22,
      "y": 1,
      "z": 3,
      "name": "Rock_Volcanic_Half"
    },
    {
      "x": -22,
      "y": 2,
      "z": 3,
      "name": "Factory_Bricks"
    },
    {
      "x": -22,
      "y": 3,
      "z": 3,
      "name": "Factory_Bricks"
    },
    {
      "x": -22,
      "y": 4,
      "z": 3,
      "name": "Factory_Bricks"
    },
    {
      "x": -22,
      "y": 5,
      "z": 3,
      "name": "Factory_Bricks"
    },
    {
      "x": -22,
      "y": 6,
      "z": 3,
      "name": "Factory_Bricks"
    },
    {
      "x": -22,
      "y": 7,
      "z": 3,
      "name": "Rock_Volcanic_Brick_Smooth"
    },
    {
      "x": -22,
      "y": 9,
      "z": 3,
      "name": "Factory_Roof_Hollow",
      "rotation": 3
    },
    {
      "x": -22,
      "y": 0,
      "z": 4,
      "name": "Soil_Dirt"
    },
    {
      "x": -22,
      "y": 1,
      "z": 4,
      "name": "Rock_Volcanic"
    },
    {
      "x": -22,
      "y": 2,
      "z": 4,
      "name": "Metal_Plate_Pillar_Base_Rusted"
    },
    {
      "x": -22,
      "y": 3,
      "z": 4,
      "name": "Metal_Plate_Pillar_Middle_Rusted"
    },
    {
      "x": -22,
      "y": 4,
      "z": 4,
      "name": "Metal_Plate_Pillar_Middle_Rusted"
    },
    {
      "x": -22,
      "y": 5,
      "z": 4,
      "name": "Metal_Plate_Pillar_Middle_Rusted"
    },
    {
      "x": -22,
      "y": 6,
      "z": 4,
      "name": "Metal_Plate_Pillar_Base_Rusted",
      "rotation": 8
    },
    {
      "x": -22,
      "y": 7,
      "z": 4,
      "name": "Rock_Volcanic_Brick"
    },
    {
      "x": -22,
      "y": 8,
      "z": 4,
      "name": "Factory_Bricks"
    },
    {
      "x": -22,
      "y": 9,
      "z": 4,
      "name": "Factory_Roof",
      "rotation": 3
    },
    {
      "x": -22,
      "y": 0,
      "z": 5,
      "name": "Soil_Dirt"
    },
    {
      "x": -22,
      "y": 1,
      "z": 5,
      "name": "Soil_Clay_Smooth_Black"
    },
    {
      "x": -22,
      "y": 9,
      "z": 5,
      "name": "Factory_Roof_Hollow",
      "rotation": 3
    },
    {
      "x": -22,
      "y": 0,
      "z": 6,
      "name": "Soil_Dirt"
    },
    {
      "x": -22,
      "y": 1,
      "z": 6,
      "name": "Soil_Clay_Smooth_Black"
    },
    {
      "x": -22,
      "y": 0,
      "z": 7,
      "name": "Soil_Dirt"
    },
    {
      "x": -22,
      "y": 1,
      "z": 7,
      "name": "Soil_Clay_Smooth_Black"
    },
    {
      "x": -22,
      "y": 0,
      "z": 8,
      "name": "Soil_Dirt"
    },
    {
      "x": -22,
      "y": 1,
      "z": 8,
      "name": "Soil_Clay_Smooth_Black"
    },
    {
      "x": -22,
      "y": 2,
      "z": 8,
      "name": "Factory_Fence_L"
    },
    {
      "x": -22,
      "y": 3,
      "z": 8,
      "name": "Factory_Fence_L",
      "filler": 1024
    },
    {
      "x": -22,
      "y": 4,
      "z": 8,
      "name": "Deco_Iron_Bars"
    },
    {
      "x": -22,
      "y": 5,
      "z": 8,
      "name": "Deco_Iron_Bars"
    },
    {
      "x": -22,
      "y": 0,
      "z": 9,
      "name": "Soil_Dirt"
    },
    {
      "x": -22,
      "y": 0,
      "z": 10,
      "name": "Soil_Dirt"
    },
    {
      "x": -22,
      "y": 0,
      "z": 11,
      "name": "Soil_Dirt"
    },
    {
      "x": -22,
      "y": 0,
      "z": 12,
      "name": "Soil_Dirt"
    },
    {
      "x": -22,
      "y": 0,
      "z": 13,
      "name": "Soil_Dirt"
    },
    {
      "x": -22,
      "y": 0,
      "z": 14,
      "name": "Soil_Dirt"
    },
    {
      "x": -22,
      "y": 0,
      "z": 15,
      "name": "Soil_Dirt"
    },
    {
      "x": -22,
      "y": 0,
      "z": 16,
      "name": "Soil_Dirt"
    },
    {
      "x": -22,
      "y": 0,
      "z": 17,
      "name": "Soil_Dirt"
    },
    {
      "x": -22,
      "y": 0,
      "z": 18,
      "name": "Soil_Dirt"
    },
    {
      "x": -22,
      "y": 0,
      "z": 19,
      "name": "Soil_Dirt"
    },
    {
      "x": -22,
      "y": 0,
      "z": 20,
      "name": "Soil_Dirt"
    },
    {
      "x": -22,
      "y": 0,
      "z": 21,
      "name": "Soil_Dirt"
    },
    {
      "x": -22,
      "y": 0,
      "z": 22,
      "name": "Soil_Dirt"
    },
    {
      "x": -21,
      "y": 0,
      "z": -26,
      "name": "Soil_Dirt"
    },
    {
      "x": -21,
      "y": 0,
      "z": -25,
      "name": "Soil_Dirt"
    },
    {
      "x": -21,
      "y": 1,
      "z": -25,
      "name": "Rock_Volcanic"
    },
    {
      "x": -21,
      "y": 2,
      "z": -25,
      "name": "Rock_Volcanic_Brick_Smooth"
    },
    {
      "x": -21,
      "y": 3,
      "z": -25,
      "name": "Rock_Volcanic_Brick_Smooth"
    },
    {
      "x": -21,
      "y": 4,
      "z": -25,
      "name": "Deco_Iron_Bars"
    },
    {
      "x": -21,
      "y": 5,
      "z": -25,
      "name": "Deco_Iron_Bars"
    },
    {
      "x": -21,
      "y": 0,
      "z": -24,
      "name": "Soil_Dirt"
    },
    {
      "x": -21,
      "y": 1,
      "z": -24,
      "name": "Rock_Volcanic_Half"
    },
    {
      "x": -21,
      "y": 0,
      "z": -23,
      "name": "Soil_Dirt"
    },
    {
      "x": -21,
      "y": 1,
      "z": -23,
      "name": "Rock_Volcanic_Half"
    },
    {
      "x": -21,
      "y": 10,
      "z": -23,
      "name": "Factory_Roof_Shallow",
      "rotation": 3
    },
    {
      "x": -21,
      "y": 0,
      "z": -22,
      "name": "Soil_Dirt"
    },
    {
      "x": -21,
      "y": 1,
      "z": -22,
      "name": "Rock_Volcanic_Half"
    },
    {
      "x": -21,
      "y": 2,
      "z": -22,
      "name": "Factory_Bricks"
    },
    {
      "x": -21,
      "y": 3,
      "z": -22,
      "name": "Factory_Bricks"
    },
    {
      "x": -21,
      "y": 4,
      "z": -22,
      "name": "Factory_Bricks"
    },
    {
      "x": -21,
      "y": 5,
      "z": -22,
      "name": "Factory_Bricks"
    },
    {
      "x": -21,
      "y": 6,
      "z": -22,
      "name": "Factory_Bricks"
    },
    {
      "x": -21,
      "y": 7,
      "z": -22,
      "name": "Factory_Bricks"
    },
    {
      "x": -21,
      "y": 8,
      "z": -22,
      "name": "Factory_Bricks"
    },
    {
      "x": -21,
      "y": 9,
      "z": -22,
      "name": "Factory_Bricks"
    },
    {
      "x": -21,
      "y": 10,
      "z": -22,
      "name": "Factory_Roof_Shallow",
      "rotation": 3
    },
    {
      "x": -21,
      "y": 0,
      "z": -21,
      "name": "Soil_Dirt"
    },
    {
      "x": -21,
      "y": 1,
      "z": -21,
      "name": "Rock_Volcanic"
    },
    {
      "x": -21,
      "y": 10,
      "z": -21,
      "name": "Factory_Roof_Shallow",
      "rotation": 3
    },
    {
      "x": -21,
      "y": 0,
      "z": -20,
      "name": "Soil_Dirt"
    },
    {
      "x": -21,
      "y": 1,
      "z": -20,
      "name": "Metal_Plate"
    },
    {
      "x": -21,
      "y": 2,
      "z": -20,
      "name": "Rock_Volcanic_Brick_Pillar_Middle"
    },
    {
      "x": -21,
      "y": 3,
      "z": -20,
      "name": "Rock_Volcanic_Brick_Pillar_Middle"
    },
    {
      "x": -21,
      "y": 4,
      "z": -20,
      "name": "Rock_Volcanic_Brick_Beam"
    },
    {
      "x": -21,
      "y": 5,
      "z": -20,
      "name": "Rock_Volcanic_Brick_Beam"
    },
    {
      "x": -21,
      "y": 6,
      "z": -20,
      "name": "Rock_Volcanic_Brick_Beam"
    },
    {
      "x": -21,
      "y": 7,
      "z": -20,
      "name": "Rock_Volcanic_Brick_Smooth"
    },
    {
      "x": -21,
      "y": 10,
      "z": -20,
      "name": "Factory_Roof_Shallow",
      "rotation": 3
    },
    {
      "x": -21,
      "y": 0,
      "z": -19,
      "name": "Soil_Dirt"
    },
    {
      "x": -21,
      "y": 1,
      "z": -19,
      "name": "Soil_Clay_Smooth_Black"
    },
    {
      "x": -21,
      "y": 7,
      "z": -19,
      "name": "Furniture_Human_Ruins_Platform"
    },
    {
      "x": -21,
      "y": 0,
      "z": -18,
      "name": "Soil_Dirt"
    },
    {
      "x": -21,
      "y": 1,
      "z": -18,
      "name": "Metal_Plate_Rusted"
    },
    {
      "x": -21,
      "y": 7,
      "z": -18,
      "name": "Furniture_Human_Ruins_Platform"
    },
    {
      "x": -21,
      "y": 0,
      "z": -17,
      "name": "Soil_Dirt"
    },
    {
      "x": -21,
      "y": 1,
      "z": -17,
      "name": "Metal_Plate"
    },
    {
      "x": -21,
      "y": 0,
      "z": -16,
      "name": "Soil_Dirt"
    },
    {
      "x": -21,
      "y": 1,
      "z": -16,
      "name": "Metal_Plate_Rusted"
    },
    {
      "x": -21,
      "y": 2,
      "z": -16,
      "name": "Rock_Ledge_Brick_Ornate"
    },
    {
      "x": -21,
      "y": 3,
      "z": -16,
      "name": "Rock_Ledge_Brick_Half"
    },
    {
      "x": -21,
      "y": 10,
      "z": -16,
      "name": "Factory_Roof_Shallow",
      "rotation": 3
    },
    {
      "x": -21,
      "y": 0,
      "z": -15,
      "name": "Soil_Dirt"
    },
    {
      "x": -21,
      "y": 1,
      "z": -15,
      "name": "Metal_Plate_Rusted"
    },
    {
      "x": -21,
      "y": 2,
      "z": -15,
      "name": "Rock_Ledge_Brick_Ornate"
    },
    {
      "x": -21,
      "y": 3,
      "z": -15,
      "name": "Rock_Ledge_Brick_Half"
    },
    {
      "x": -21,
      "y": 10,
      "z": -15,
      "name": "Factory_Roof_Shallow",
      "rotation": 3
    },
    {
      "x": -21,
      "y": 0,
      "z": -14,
      "name": "Soil_Dirt"
    },
    {
      "x": -21,
      "y": 1,
      "z": -14,
      "name": "Soil_Clay_Smooth_Black"
    },
    {
      "x": -21,
      "y": 10,
      "z": -14,
      "name": "Factory_Roof_Shallow",
      "rotation": 3
    },
    {
      "x": -21,
      "y": 0,
      "z": -13,
      "name": "Soil_Dirt"
    },
    {
      "x": -21,
      "y": 1,
      "z": -13,
      "name": "Soil_Clay_Smooth_Black"
    },
    {
      "x": -21,
      "y": 10,
      "z": -13,
      "name": "Factory_Roof_Shallow",
      "rotation": 3
    },
    {
      "x": -21,
      "y": 0,
      "z": -12,
      "name": "Soil_Dirt"
    },
    {
      "x": -21,
      "y": 1,
      "z": -12,
      "name": "Soil_Clay_Smooth_Black"
    },
    {
      "x": -21,
      "y": 7,
      "z": -12,
      "name": "Furniture_Human_Ruins_Platform",
      "rotation": 1
    },
    {
      "x": -21,
      "y": 10,
      "z": -12,
      "name": "Factory_Roof_Shallow",
      "rotation": 3
    },
    {
      "x": -21,
      "y": 0,
      "z": -11,
      "name": "Soil_Dirt"
    },
    {
      "x": -21,
      "y": 1,
      "z": -11,
      "name": "Soil_Dirt_Burnt"
    },
    {
      "x": -21,
      "y": 2,
      "z": -11,
      "name": "Rock_Volcanic_Brick_Pillar_Middle"
    },
    {
      "x": -21,
      "y": 3,
      "z": -11,
      "name": "Rock_Volcanic_Brick_Pillar_Middle"
    },
    {
      "x": -21,
      "y": 4,
      "z": -11,
      "name": "Rock_Volcanic_Brick_Beam"
    },
    {
      "x": -21,
      "y": 5,
      "z": -11,
      "name": "Rock_Volcanic_Brick_Beam"
    },
    {
      "x": -21,
      "y": 6,
      "z": -11,
      "name": "Rock_Volcanic_Brick_Beam"
    },
    {
      "x": -21,
      "y": 7,
      "z": -11,
      "name": "Rock_Volcanic_Brick_Smooth"
    },
    {
      "x": -21,
      "y": 10,
      "z": -11,
      "name": "Factory_Roof_Shallow",
      "rotation": 3
    },
    {
      "x": -21,
      "y": 0,
      "z": -10,
      "name": "Soil_Dirt"
    },
    {
      "x": -21,
      "y": 1,
      "z": -10,
      "name": "Soil_Clay_Smooth_Black"
    },
    {
      "x": -21,
      "y": 7,
      "z": -10,
      "name": "Furniture_Human_Ruins_Platform",
      "rotation": 1
    },
    {
      "x": -21,
      "y": 0,
      "z": -9,
      "name": "Soil_Dirt"
    },
    {
      "x": -21,
      "y": 1,
      "z": -9,
      "name": "Soil_Clay_Smooth_Black"
    },
    {
      "x": -21,
      "y": 7,
      "z": -9,
      "name": "Furniture_Human_Ruins_Platform",
      "rotation": 1
    },
    {
      "x": -21,
      "y": 0,
      "z": -8,
      "name": "Soil_Dirt"
    },
    {
      "x": -21,
      "y": 1,
      "z": -8,
      "name": "Soil_Clay_Smooth_Black"
    },
    {
      "x": -21,
      "y": 2,
      "z": -8,
      "name": "Rock_Volcanic_Brick_Pillar_Middle"
    },
    {
      "x": -21,
      "y": 3,
      "z": -8,
      "name": "Rock_Volcanic_Brick_Pillar_Middle"
    },
    {
      "x": -21,
      "y": 4,
      "z": -8,
      "name": "Rock_Volcanic_Brick_Beam"
    },
    {
      "x": -21,
      "y": 5,
      "z": -8,
      "name": "Rock_Volcanic_Brick_Beam"
    },
    {
      "x": -21,
      "y": 6,
      "z": -8,
      "name": "Rock_Volcanic_Brick_Beam"
    },
    {
      "x": -21,
      "y": 7,
      "z": -8,
      "name": "Rock_Volcanic_Brick_Smooth"
    },
    {
      "x": -21,
      "y": 0,
      "z": -7,
      "name": "Soil_Dirt"
    },
    {
      "x": -21,
      "y": 1,
      "z": -7,
      "name": "Metal_Plate_Rusted"
    },
    {
      "x": -21,
      "y": 7,
      "z": -7,
      "name": "Furniture_Human_Ruins_Platform",
      "rotation": 1
    },
    {
      "x": -21,
      "y": 10,
      "z": -7,
      "name": "Factory_Roof_Shallow",
      "rotation": 3
    },
    {
      "x": -21,
      "y": 0,
      "z": -6,
      "name": "Soil_Dirt"
    },
    {
      "x": -21,
      "y": 1,
      "z": -6,
      "name": "Metal_Plate_Rusted"
    },
    {
      "x": -21,
      "y": 7,
      "z": -6,
      "name": "Furniture_Human_Ruins_Platform",
      "rotation": 1
    },
    {
      "x": -21,
      "y": 10,
      "z": -6,
      "name": "Factory_Roof_Shallow",
      "rotation": 3
    },
    {
      "x": -21,
      "y": 0,
      "z": -5,
      "name": "Soil_Dirt"
    },
    {
      "x": -21,
      "y": 1,
      "z": -5,
      "name": "Soil_Clay_Smooth_Black"
    },
    {
      "x": -21,
      "y": 10,
      "z": -5,
      "name": "Factory_Roof_Shallow",
      "rotation": 3
    },
    {
      "x": -21,
      "y": 0,
      "z": -4,
      "name": "Soil_Dirt"
    },
    {
      "x": -21,
      "y": 1,
      "z": -4,
      "name": "Soil_Clay_Smooth_Black"
    },
    {
      "x": -21,
      "y": 10,
      "z": -4,
      "name": "Factory_Roof_Shallow",
      "rotation": 3
    },
    {
      "x": -21,
      "y": 0,
      "z": -3,
      "name": "Soil_Dirt"
    },
    {
      "x": -21,
      "y": 1,
      "z": -3,
      "name": "Rock_Volcanic"
    },
    {
      "x": -21,
      "y": 7,
      "z": -3,
      "name": "Furniture_Human_Ruins_Platform",
      "rotation": 1
    },
    {
      "x": -21,
      "y": 10,
      "z": -3,
      "name": "Factory_Roof_Shallow",
      "rotation": 3
    },
    {
      "x": -21,
      "y": 0,
      "z": -2,
      "name": "Soil_Dirt"
    },
    {
      "x": -21,
      "y": 1,
      "z": -2,
      "name": "Rock_Volcanic_Half"
    },
    {
      "x": -21,
      "y": 7,
      "z": -2,
      "name": "Furniture_Human_Ruins_Platform",
      "rotation": 1
    },
    {
      "x": -21,
      "y": 10,
      "z": -2,
      "name": "Factory_Roof_Shallow",
      "rotation": 3
    },
    {
      "x": -21,
      "y": 0,
      "z": -1,
      "name": "Soil_Dirt"
    },
    {
      "x": -21,
      "y": 1,
      "z": -1,
      "name": "Metal_Plate_Rusted"
    },
    {
      "x": -21,
      "y": 7,
      "z": -1,
      "name": "Furniture_Human_Ruins_Platform",
      "rotation": 1
    },
    {
      "x": -21,
      "y": 0,
      "z": 0,
      "name": "Soil_Dirt"
    },
    {
      "x": -21,
      "y": 1,
      "z": 0,
      "name": "Metal_Plate_Rusted"
    },
    {
      "x": -21,
      "y": 7,
      "z": 0,
      "name": "Furniture_Human_Ruins_Platform",
      "rotation": 1
    },
    {
      "x": -21,
      "y": 10,
      "z": 0,
      "name": "Factory_Roof_Shallow",
      "rotation": 3
    },
    {
      "x": -21,
      "y": 0,
      "z": 1,
      "name": "Soil_Dirt"
    },
    {
      "x": -21,
      "y": 1,
      "z": 1,
      "name": "Rock_Volcanic"
    },
    {
      "x": -21,
      "y": 7,
      "z": 1,
      "name": "Furniture_Human_Ruins_Platform"
    },
    {
      "x": -21,
      "y": 10,
      "z": 1,
      "name": "Factory_Roof_Shallow",
      "rotation": 3
    },
    {
      "x": -21,
      "y": 0,
      "z": 2,
      "name": "Soil_Dirt"
    },
    {
      "x": -21,
      "y": 1,
      "z": 2,
      "name": "Soil_Dirt_Burnt"
    },
    {
      "x": -21,
      "y": 2,
      "z": 2,
      "name": "Rock_Volcanic_Brick_Pillar_Middle"
    },
    {
      "x": -21,
      "y": 3,
      "z": 2,
      "name": "Rock_Volcanic_Brick_Pillar_Middle"
    },
    {
      "x": -21,
      "y": 4,
      "z": 2,
      "name": "Rock_Volcanic_Brick_Beam"
    },
    {
      "x": -21,
      "y": 5,
      "z": 2,
      "name": "Rock_Volcanic_Brick_Beam"
    },
    {
      "x": -21,
      "y": 6,
      "z": 2,
      "name": "Rock_Volcanic_Brick_Beam"
    },
    {
      "x": -21,
      "y": 7,
      "z": 2,
      "name": "Rock_Volcanic_Brick_Smooth"
    },
    {
      "x": -21,
      "y": 10,
      "z": 2,
      "name": "Factory_Roof_Shallow",
      "rotation": 3
    },
    {
      "x": -21,
      "y": 0,
      "z": 3,
      "name": "Soil_Dirt"
    },
    {
      "x": -21,
      "y": 1,
      "z": 3,
      "name": "Soil_Dirt_Burnt"
    },
    {
      "x": -21,
      "y": 10,
      "z": 3,
      "name": "Factory_Roof_Shallow",
      "rotation": 3
    },
    {
      "x": -21,
      "y": 0,
      "z": 4,
      "name": "Soil_Dirt"
    },
    {
      "x": -21,
      "y": 1,
      "z": 4,
      "name": "Rock_Volcanic_Half"
    },
    {
      "x": -21,
      "y": 2,
      "z": 4,
      "name": "Factory_Bricks"
    },
    {
      "x": -21,
      "y": 3,
      "z": 4,
      "name": "Factory_Bricks"
    },
    {
      "x": -21,
      "y": 4,
      "z": 4,
      "name": "Factory_Bricks"
    },
    {
      "x": -21,
      "y": 5,
      "z": 4,
      "name": "Factory_Bricks"
    },
    {
      "x": -21,
      "y": 6,
      "z": 4,
      "name": "Factory_Bricks"
    },
    {
      "x": -21,
      "y": 7,
      "z": 4,
      "name": "Factory_Bricks"
    },
    {
      "x": -21,
      "y": 8,
      "z": 4,
      "name": "Factory_Bricks"
    },
    {
      "x": -21,
      "y": 9,
      "z": 4,
      "name": "Factory_Bricks"
    },
    {
      "x": -21,
      "y": 10,
      "z": 4,
      "name": "Factory_Roof_Shallow",
      "rotation": 3
    },
    {
      "x": -21,
      "y": 0,
      "z": 5,
      "name": "Soil_Dirt"
    },
    {
      "x": -21,
      "y": 1,
      "z": 5,
      "name": "Soil_Clay_Smooth_Black"
    },
    {
      "x": -21,
      "y": 10,
      "z": 5,
      "name": "Factory_Roof_Shallow",
      "rotation": 3
    },
    {
      "x": -21,
      "y": 0,
      "z": 6,
      "name": "Soil_Dirt"
    },
    {
      "x": -21,
      "y": 1,
      "z": 6,
      "name": "Rock_Volcanic_Half"
    },
    {
      "x": -21,
      "y": 2,
      "z": 6,
      "name": "Plant_Leaves_Burnt"
    },
    {
      "x": -21,
      "y": 0,
      "z": 7,
      "name": "Soil_Dirt"
    },
    {
      "x": -21,
      "y": 1,
      "z": 7,
      "name": "Soil_Clay_Smooth_Black"
    },
    {
      "x": -21,
      "y": 0,
      "z": 8,
      "name": "Soil_Dirt"
    },
    {
      "x": -21,
      "y": 1,
      "z": 8,
      "name": "Rock_Volcanic"
    },
    {
      "x": -21,
      "y": 2,
      "z": 8,
      "name": "Rock_Volcanic_Brick_Smooth"
    },
    {
      "x": -21,
      "y": 3,
      "z": 8,
      "name": "Rock_Volcanic_Brick_Smooth"
    },
    {
      "x": -21,
      "y": 4,
      "z": 8,
      "name": "Rock_Volcanic_Brick_Smooth"
    },
    {
      "x": -21,
      "y": 5,
      "z": 8,
      "name": "Deco_Iron_Bars"
    },
    {
      "x": -21,
      "y": 0,
      "z": 9,
      "name": "Soil_Dirt"
    },
    {
      "x": -21,
      "y": 0,
      "z": 10,
      "name": "Soil_Dirt"
    },
    {
      "x": -21,
      "y": 0,
      "z": 11,
      "name": "Soil_Dirt"
    },
    {
      "x": -21,
      "y": 0,
      "z": 12,
      "name": "Soil_Dirt"
    },
    {
      "x": -21,
      "y": 0,
      "z": 13,
      "name": "Soil_Dirt"
    },
    {
      "x": -21,
      "y": 0,
      "z": 14,
      "name": "Soil_Dirt"
    },
    {
      "x": -21,
      "y": 0,
      "z": 15,
      "name": "Soil_Dirt"
    },
    {
      "x": -21,
      "y": 0,
      "z": 16,
      "name": "Soil_Dirt"
    },
    {
      "x": -21,
      "y": 0,
      "z": 17,
      "name": "Soil_Dirt"
    },
    {
      "x": -21,
      "y": 0,
      "z": 18,
      "name": "Soil_Dirt"
    },
    {
      "x": -21,
      "y": 0,
      "z": 19,
      "name": "Soil_Dirt"
    },
    {
      "x": -21,
      "y": 0,
      "z": 20,
      "name": "Soil_Dirt"
    },
    {
      "x": -21,
      "y": 0,
      "z": 21,
      "name": "Soil_Dirt"
    },
    {
      "x": -21,
      "y": 0,
      "z": 22,
      "name": "Soil_Dirt"
    },
    {
      "x": -21,
      "y": 0,
      "z": 23,
      "name": "Soil_Dirt"
    },
    {
      "x": -21,
      "y": 0,
      "z": 24,
      "name": "Soil_Dirt"
    },
    {
      "x": -21,
      "y": 0,
      "z": 25,
      "name": "Soil_Dirt"
    },
    {
      "x": -21,
      "y": 0,
      "z": 26,
      "name": "Soil_Dirt"
    },
    {
      "x": -20,
      "y": 0,
      "z": -26,
      "name": "Soil_Dirt"
    },
    {
      "x": -20,
      "y": 0,
      "z": -25,
      "name": "Soil_Dirt"
    },
    {
      "x": -20,
      "y": 1,
      "z": -25,
      "name": "Soil_Clay_Smooth_Black"
    },
    {
      "x": -20,
      "y": 2,
      "z": -25,
      "name": "Rock_Volcanic_Brick_Ornate"
    },
    {
      "x": -20,
      "y": 3,
      "z": -25,
      "name": "Rock_Volcanic_Brick_Decorative"
    },
    {
      "x": -20,
      "y": 4,
      "z": -25,
      "name": "Rock_Volcanic_Brick_Smooth"
    },
    {
      "x": -20,
      "y": 5,
      "z": -25,
      "name": "Rock_Volcanic_Brick"
    },
    {
      "x": -20,
      "y": 0,
      "z": -24,
      "name": "Soil_Dirt"
    },
    {
      "x": -20,
      "y": 1,
      "z": -24,
      "name": "Soil_Clay_Smooth_Black"
    },
    {
      "x": -20,
      "y": 0,
      "z": -23,
      "name": "Soil_Dirt"
    },
    {
      "x": -20,
      "y": 1,
      "z": -23,
      "name": "Rock_Volcanic"
    },
    {
      "x": -20,
      "y": 10,
      "z": -23,
      "name": "Factory_Roof_Shallow",
      "filler": 1,
      "rotation": 3
    },
    {
      "x": -20,
      "y": 0,
      "z": -22,
      "name": "Soil_Dirt"
    },
    {
      "x": -20,
      "y": 1,
      "z": -22,
      "name": "Rock_Volcanic_Half"
    },
    {
      "x": -20,
      "y": 2,
      "z": -22,
      "name": "Factory_Bricks"
    },
    {
      "x": -20,
      "y": 3,
      "z": -22,
      "name": "Factory_Bricks"
    },
    {
      "x": -20,
      "y": 4,
      "z": -22,
      "name": "Rock_Volcanic_Brick_Smooth",
      "rotation": 1
    },
    {
      "x": -20,
      "y": 5,
      "z": -22,
      "name": "Rock_Volcanic_Brick"
    },
    {
      "x": -20,
      "y": 6,
      "z": -22,
      "name": "Rock_Volcanic_Brick"
    },
    {
      "x": -20,
      "y": 7,
      "z": -22,
      "name": "Rock_Volcanic_Brick_Smooth"
    },
    {
      "x": -20,
      "y": 10,
      "z": -22,
      "name": "Factory_Roof_Shallow",
      "filler": 1,
      "rotation": 3
    },
    {
      "x": -20,
      "y": 0,
      "z": -21,
      "name": "Soil_Dirt"
    },
    {
      "x": -20,
      "y": 1,
      "z": -21,
      "name": "Rock_Volcanic"
    },
    {
      "x": -20,
      "y": 10,
      "z": -21,
      "name": "Factory_Roof_Shallow",
      "filler": 1,
      "rotation": 3
    },
    {
      "x": -20,
      "y": 0,
      "z": -20,
      "name": "Soil_Dirt"
    },
    {
      "x": -20,
      "y": 1,
      "z": -20,
      "name": "Metal_Plate_Rusted"
    },
    {
      "x": -20,
      "y": 5,
      "z": -20,
      "name": "Deco_Iron_Chain_Small"
    },
    {
      "x": -20,
      "y": 6,
      "z": -20,
      "name": "Deco_Iron_Chain_Small"
    },
    {
      "x": -20,
      "y": 7,
      "z": -20,
      "name": "Factory_Girder_Full",
      "rotation": 5
    },
    {
      "x": -20,
      "y": 10,
      "z": -20,
      "name": "Factory_Roof_Shallow",
      "filler": 1,
      "rotation": 3
    },
    {
      "x": -20,
      "y": 0,
      "z": -19,
      "name": "Soil_Dirt"
    },
    {
      "x": -20,
      "y": 1,
      "z": -19,
      "name": "Metal_Plate_Rusted"
    },
    {
      "x": -20,
      "y": 0,
      "z": -18,
      "name": "Soil_Dirt"
    },
    {
      "x": -20,
      "y": 1,
      "z": -18,
      "name": "Metal_Plate_Rusted"
    },
    {
      "x": -20,
      "y": 0,
      "z": -17,
      "name": "Soil_Dirt"
    },
    {
      "x": -20,
      "y": 1,
      "z": -17,
      "name": "Metal_Plate_Rusted"
    },
    {
      "x": -20,
      "y": 0,
      "z": -16,
      "name": "Soil_Dirt"
    },
    {
      "x": -20,
      "y": 1,
      "z": -16,
      "name": "Rock_Volcanic"
    },
    {
      "x": -20,
      "y": 2,
      "z": -16,
      "name": "Rock_Ledge_Brick_Ornate"
    },
    {
      "x": -20,
      "y": 3,
      "z": -16,
      "name": "Rock_Ledge_Brick_Half"
    },
    {
      "x": -20,
      "y": 10,
      "z": -16,
      "name": "Factory_Roof_Shallow",
      "filler": 1,
      "rotation": 3
    },
    {
      "x": -20,
      "y": 0,
      "z": -15,
      "name": "Soil_Dirt"
    },
    {
      "x": -20,
      "y": 1,
      "z": -15,
      "name": "Soil_Dirt_Burnt"
    },
    {
      "x": -20,
      "y": 2,
      "z": -15,
      "name": "Rock_Ledge_Brick_Ornate"
    },
    {
      "x": -20,
      "y": 3,
      "z": -15,
      "name": "Rock_Ledge_Brick_Half"
    },
    {
      "x": -20,
      "y": 10,
      "z": -15,
      "name": "Factory_Roof_Shallow",
      "filler": 1,
      "rotation": 3
    },
    {
      "x": -20,
      "y": 0,
      "z": -14,
      "name": "Soil_Dirt"
    },
    {
      "x": -20,
      "y": 1,
      "z": -14,
      "name": "Rock_Volcanic"
    },
    {
      "x": -20,
      "y": 10,
      "z": -14,
      "name": "Factory_Roof_Shallow",
      "filler": 1,
      "rotation": 3
    },
    {
      "x": -20,
      "y": 0,
      "z": -13,
      "name": "Soil_Dirt"
    },
    {
      "x": -20,
      "y": 1,
      "z": -13,
      "name": "Soil_Dirt_Burnt"
    },
    {
      "x": -20,
      "y": 10,
      "z": -13,
      "name": "Factory_Roof_Shallow",
      "filler": 1,
      "rotation": 3
    },
    {
      "x": -20,
      "y": 0,
      "z": -12,
      "name": "Soil_Dirt"
    },
    {
      "x": -20,
      "y": 1,
      "z": -12,
      "name": "Soil_Clay_Smooth_Black"
    },
    {
      "x": -20,
      "y": 10,
      "z": -12,
      "name": "Factory_Roof_Shallow",
      "filler": 1,
      "rotation": 3
    },
    {
      "x": -20,
      "y": 0,
      "z": -11,
      "name": "Soil_Dirt"
    },
    {
      "x": -20,
      "y": 1,
      "z": -11,
      "name": "Soil_Dirt_Burnt"
    },
    {
      "x": -20,
      "y": 7,
      "z": -11,
      "name": "Factory_Girder_Full",
      "rotation": 5
    },
    {
      "x": -20,
      "y": 10,
      "z": -11,
      "name": "Factory_Roof_Shallow",
      "filler": 1,
      "rotation": 3
    },
    {
      "x": -20,
      "y": 0,
      "z": -10,
      "name": "Soil_Dirt"
    },
    {
      "x": -20,
      "y": 1,
      "z": -10,
      "name": "Soil_Clay_Smooth_Black"
    },
    {
      "x": -20,
      "y": 0,
      "z": -9,
      "name": "Soil_Dirt"
    },
    {
      "x": -20,
      "y": 1,
      "z": -9,
      "name": "Soil_Dirt_Burnt"
    },
    {
      "x": -20,
      "y": 0,
      "z": -8,
      "name": "Soil_Dirt"
    },
    {
      "x": -20,
      "y": 1,
      "z": -8,
      "name": "Metal_Plate_Rusted"
    },
    {
      "x": -20,
      "y": 7,
      "z": -8,
      "name": "Factory_Girder_Full",
      "rotation": 5
    },
    {
      "x": -20,
      "y": 0,
      "z": -7,
      "name": "Soil_Dirt"
    },
    {
      "x": -20,
      "y": 1,
      "z": -7,
      "name": "Metal_Plate_Rusted"
    },
    {
      "x": -20,
      "y": 10,
      "z": -7,
      "name": "Factory_Roof_Shallow",
      "filler": 1,
      "rotation": 3
    },
    {
      "x": -20,
      "y": 0,
      "z": -6,
      "name": "Soil_Dirt"
    },
    {
      "x": -20,
      "y": 1,
      "z": -6,
      "name": "Metal_Plate_Rusted"
    },
    {
      "x": -20,
      "y": 10,
      "z": -6,
      "name": "Factory_Roof_Shallow",
      "filler": 1,
      "rotation": 3
    },
    {
      "x": -20,
      "y": 0,
      "z": -5,
      "name": "Soil_Dirt"
    },
    {
      "x": -20,
      "y": 1,
      "z": -5,
      "name": "Metal_Plate_Rusted"
    },
    {
      "x": -20,
      "y": 10,
      "z": -5,
      "name": "Factory_Roof_Shallow",
      "filler": 1,
      "rotation": 3
    },
    {
      "x": -20,
      "y": 0,
      "z": -4,
      "name": "Soil_Dirt"
    },
    {
      "x": -20,
      "y": 1,
      "z": -4,
      "name": "Metal_Plate"
    },
    {
      "x": -20,
      "y": 10,
      "z": -4,
      "name": "Factory_Roof_Shallow",
      "filler": 1,
      "rotation": 3
    },
    {
      "x": -20,
      "y": 0,
      "z": -3,
      "name": "Soil_Dirt"
    },
    {
      "x": -20,
      "y": 1,
      "z": -3,
      "name": "Metal_Plate"
    },
    {
      "x": -20,
      "y": 10,
      "z": -3,
      "name": "Factory_Roof_Shallow",
      "filler": 1,
      "rotation": 3
    },
    {
      "x": -20,
      "y": 0,
      "z": -2,
      "name": "Soil_Dirt"
    },
    {
      "x": -20,
      "y": 1,
      "z": -2,
      "name": "Rock_Volcanic"
    },
    {
      "x": -20,
      "y": 10,
      "z": -2,
      "name": "Factory_Roof_Shallow",
      "filler": 1,
      "rotation": 3
    },
    {
      "x": -20,
      "y": 0,
      "z": -1,
      "name": "Soil_Dirt"
    },
    {
      "x": -20,
      "y": 1,
      "z": -1,
      "name": "Metal_Plate_Rusted"
    },
    {
      "x": -20,
      "y": 0,
      "z": 0,
      "name": "Soil_Dirt"
    },
    {
      "x": -20,
      "y": 1,
      "z": 0,
      "name": "Metal_Plate_Rusted"
    },
    {
      "x": -20,
      "y": 10,
      "z": 0,
      "name": "Factory_Roof_Shallow",
      "filler": 1,
      "rotation": 3
    },
    {
      "x": -20,
      "y": 0,
      "z": 1,
      "name": "Soil_Dirt"
    },
    {
      "x": -20,
      "y": 1,
      "z": 1,
      "name": "Metal_Plate_Rusted"
    },
    {
      "x": -20,
      "y": 10,
      "z": 1,
      "name": "Factory_Roof_Shallow",
      "filler": 1,
      "rotation": 3
    },
    {
      "x": -20,
      "y": 0,
      "z": 2,
      "name": "Soil_Dirt"
    },
    {
      "x": -20,
      "y": 1,
      "z": 2,
      "name": "Soil_Dirt_Burnt"
    },
    {
      "x": -20,
      "y": 7,
      "z": 2,
      "name": "Factory_Girder_Full",
      "rotation": 5
    },
    {
      "x": -20,
      "y": 10,
      "z": 2,
      "name": "Factory_Roof_Shallow",
      "filler": 1,
      "rotation": 3
    },
    {
      "x": -20,
      "y": 0,
      "z": 3,
      "name": "Soil_Dirt"
    },
    {
      "x": -20,
      "y": 1,
      "z": 3,
      "name": "Soil_Clay_Smooth_Black"
    },
    {
      "x": -20,
      "y": 10,
      "z": 3,
      "name": "Factory_Roof_Shallow",
      "filler": 1,
      "rotation": 3
    },
    {
      "x": -20,
      "y": 0,
      "z": 4,
      "name": "Soil_Dirt"
    },
    {
      "x": -20,
      "y": 1,
      "z": 4,
      "name": "Soil_Clay_Smooth_Black"
    },
    {
      "x": -20,
      "y": 2,
      "z": 4,
      "name": "Factory_Bricks"
    },
    {
      "x": -20,
      "y": 3,
      "z": 4,
      "name": "Factory_Bricks"
    },
    {
      "x": -20,
      "y": 4,
      "z": 4,
      "name": "Rock_Volcanic_Brick",
      "rotation": 3
    },
    {
      "x": -20,
      "y": 5,
      "z": 4,
      "name": "Rock_Volcanic_Brick",
      "rotation": 3
    },
    {
      "x": -20,
      "y": 8,
      "z": 4,
      "name": "Rock_Volcanic_Brick"
    },
    {
      "x": -20,
      "y": 9,
      "z": 4,
      "name": "Rock_Volcanic_Brick"
    },
    {
      "x": -20,
      "y": 10,
      "z": 4,
      "name": "Factory_Roof_Shallow",
      "filler": 1,
      "rotation": 3
    },
    {
      "x": -20,
      "y": 0,
      "z": 5,
      "name": "Soil_Dirt"
    },
    {
      "x": -20,
      "y": 1,
      "z": 5,
      "name": "Rock_Volcanic"
    },
    {
      "x": -20,
      "y": 10,
      "z": 5,
      "name": "Factory_Roof_Shallow",
      "filler": 1,
      "rotation": 3
    },
    {
      "x": -20,
      "y": 0,
      "z": 6,
      "name": "Soil_Dirt"
    },
    {
      "x": -20,
      "y": 1,
      "z": 6,
      "name": "Soil_Clay_Smooth_Black"
    },
    {
      "x": -20,
      "y": 2,
